Workbook

Sheet ★ Ablation-Study
A1: Model | B1: Config | C1: Spalte2 | D1: Spalte1 | E1: Avg Accuracy [%] | F1: Std Accuracy [%] | G1: Min Accuracy [%] | H1: Max Accuracy [%] | I1: Avg Cost [USD] | J1: Total Cost [USD] | K1: Avg Duration [s] | L1: Avg Total Tokens | M1: Avg Input Tokens | N1: Avg Output Tokens | O1: Cost per Acc Point | P1: Runs | Q1: Evaluated Layers
A2: gpt-4o-mini | B2: C8_BatchFiltered_NoName | C2: =_xlfn.XLOOKUP(Tabelle2[[#This Row],[Config]],Tabelle2!$A$1:$A$8,Tabelle2!$B$1:$B$8) -> P7 | D2: =Tabelle2[[#This Row],[Model]] & " | " & Tabelle2[[#This Row],[Spalte2]] -> gpt-4o-mini | P7 | E2: =SUMPRODUCT(('Benchmark-Runs'!$X$2:$X$161=A2&"_"&B2)*('Benchmark-Runs'!$W$2:$W$161))/COUNTIF('Benchmark-Runs'!$X$2:$X$161,A2&"_"&B2) -> 80 | F2: =IFERROR(SQRT(SUMPRODUCT(('Benchmark-Runs'!$X$2:$X$161=A2&"_"&B2)*('Benchmark-Runs'!$W$2:$W$161)^2)/COUNTIF('Benchmark-Runs'!$X$2:$X$161,A2&"_"&B2)-(SUMPRODUCT(('Benchmark-Runs'!$X$2:$X$161=A2&"_"&B2)*('Benchmark-Runs'!$W$2:$W$161))/COUNTIF('Benchmark-Runs'!$X$2:$X$161,A2&"_"&B2))^2),0) -> 16.329932 | G2: =_xlfn.SINGLE(_xlfn.MINIFS('Benchmark-Runs'!$W$2:$W$161,'Benchmark-Runs'!$X$2:$X$161,A2&"_"&B2)) -> 66.666667 | H2: =_xlfn.SINGLE(_xlfn.MAXIFS('Benchmark-Runs'!$W$2:$W$161,'Benchmark-Runs'!$X$2:$X$161,A2&"_"&B2)) -> 100 | I2: =SUMPRODUCT(('Benchmark-Runs'!$X$2:$X$161=A2&"_"&B2)*('Benchmark-Runs'!$F$2:$F$161))/COUNTIF('Benchmark-Runs'!$X$2:$X$161,A2&"_"&B2) -> 0.0009244 | J2: =SUMPRODUCT(('Benchmark-Runs'!$X$2:$X$161=A2&"_"&B2)*('Benchmark-Runs'!$F$2:$F$161)) -> 0.004622 | K2: =SUMPRODUCT(('Benchmark-Runs'!$X$2:$X$161=A2&"_"&B2)*('Benchmark-Runs'!$E$2:$E$161))/COUNTIF('Benchmark-Runs'!$X$2:$X$161,A2&"_"&B2) -> 9.282 | L2: =SUMPRODUCT(('Benchmark-Runs'!$X$2:$X$161=A2&"_"&B2)*('Benchmark-Runs'!$I$2:$I$161))/COUNTIF('Benchmark-Runs'!$X$2:$X$161,A2&"_"&B2) -> 4854.8 | M2: =SUMPRODUCT(('Benchmark-Runs'!$X$2:$X$161=A2&"_"&B2)*('Benchmark-Runs'!$G$2:$G$161))/COUNTIF('Benchmark-Runs'!$X$2:$X$161,A2&"_"&B2) -> 4419 | N2: =SUMPRODUCT(('Benchmark-Runs'!$X$2:$X$161=A2&"_"&B2)*('Benchmark-Runs'!$H$2:$H$161))/COUNTIF('Benchmark-Runs'!$X$2:$X$161,A2&"_"&B2) -> 435.8 | O2: =IFERROR(I2/E2,"-") -> 1.1555e-05 | P2: =COUNTIF('Benchmark-Runs'!$X$2:$X$161,A2&"_"&B2) -> 5 | Q2: =IFERROR(SUMPRODUCT(('Benchmark-Runs'!$X$2:$X$161=A2&"_"&B2)*('Benchmark-Runs'!$V$2:$V$161))/COUNTIF('Benchmark-Runs'!$X$2:$X$161,A2&"_"&B2),"-") -> 3
A3: gpt-4o-mini | B3: C5_BatchFiltered | C3: =_xlfn.XLOOKUP(Tabelle2[[#This Row],[Config]],Tabelle2!$A$1:$A$8,Tabelle2!$B$1:$B$8) -> P8 | D3: =Tabelle2[[#This Row],[Model]] & " | " & Tabelle2[[#This Row],[Spalte2]] -> gpt-4o-mini | P8 | E3: =SUMPRODUCT(('Benchmark-Runs'!$X$2:$X$161=A3&"_"&B3)*('Benchmark-Runs'!$W$2:$W$161))/COUNTIF('Benchmark-Runs'!$X$2:$X$161,A3&"_"&B3) -> 66.666667 | F3: =IFERROR(SQRT(SUMPRODUCT(('Benchmark-Runs'!$X$2:$X$161=A3&"_"&B3)*('Benchmark-Runs'!$W$2:$W$161)^2)/COUNTIF('Benchmark-Runs'!$X$2:$X$161,A3&"_"&B3)-(SUMPRODUCT(('Benchmark-Runs'!$X$2:$X$161=A3&"_"&B3)*('Benchmark-Runs'!$W$2:$W$161))/COUNTIF('Benchmark-Runs'!$X$2:$X$161,A3&"_"&B3))^2),0) -> 0 | G3: =_xlfn.SINGLE(_xlfn.MINIFS('Benchmark-Runs'!$W$2:$W$161,'Benchmark-Runs'!$X$2:$X$161,A3&"_"&B3)) -> 66.666667 | H3: =_xlfn.SINGLE(_xlfn.MAXIFS('Benchmark-Runs'!$W$2:$W$161,'Benchmark-Runs'!$X$2:$X$161,A3&"_"&B3)) -> 66.666667 | I3: =SUMPRODUCT(('Benchmark-Runs'!$X$2:$X$161=A3&"_"&B3)*('Benchmark-Runs'!$F$2:$F$161))/COUNTIF('Benchmark-Runs'!$X$2:$X$161,A3&"_"&B3) -> 0.000941 | J3: =SUMPRODUCT(('Benchmark-Runs'!$X$2:$X$161=A3&"_"&B3)*('Benchmark-Runs'!$F$2:$F$161)) -> 0.004705 | K3: =SUMPRODUCT(('Benchmark-Runs'!$X$2:$X$161=A3&"_"&B3)*('Benchmark-Runs'!$E$2:$E$161))/COUNTIF('Benchmark-Runs'!$X$2:$X$161,A3&"_"&B3) -> 8.8 | L3: =SUMPRODUCT(('Benchmark-Runs'!$X$2:$X$161=A3&"_"&B3)*('Benchmark-Runs'!$I$2:$I$161))/COUNTIF('Benchmark-Runs'!$X$2:$X$161,A3&"_"&B3) -> 4882.8 | M3: =SUMPRODUCT(('Benchmark-Runs'!$X$2:$X$161=A3&"_"&B3)*('Benchmark-Runs'!$G$2:$G$161))/COUNTIF('Benchmark-Runs'!$X$2:$X$161,A3&"_"&B3) -> 4419 | N3: =SUMPRODUCT(('Benchmark-Runs'!$X$2:$X$161=A3&"_"&B3)*('Benchmark-Runs'!$H$2:$H$161))/COUNTIF('Benchmark-Runs'!$X$2:$X$161,A3&"_"&B3) -> 463.8 | O3: =IFERROR(I3/E3,"-") -> 1.4115e-05 | P3: =COUNTIF('Benchmark-Runs'!$X$2:$X$161,A3&"_"&B3) -> 5 | Q3: =IFERROR(SUMPRODUCT(('Benchmark-Runs'!$X$2:$X$161=A3&"_"&B3)*('Benchmark-Runs'!$V$2:$V$161))/COUNTIF('Benchmark-Runs'!$X$2:$X$161,A3&"_"&B3),"-") -> 3
A4: gpt-4o-mini | B4: C7_FilterOnly | C4: =_xlfn.XLOOKUP(Tabelle2[[#This Row],[Config]],Tabelle2!$A$1:$A$8,Tabelle2!$B$1:$B$8) -> P3 | D4: =Tabelle2[[#This Row],[Model]] & " | " & Tabelle2[[#This Row],[Spalte2]] -> gpt-4o-mini | P3 | E4: =SUMPRODUCT(('Benchmark-Runs'!$X$2:$X$161=A4&"_"&B4)*('Benchmark-Runs'!$W$2:$W$161))/COUNTIF('Benchmark-Runs'!$X$2:$X$161,A4&"_"&B4) -> 100 | F4: =IFERROR(SQRT(SUMPRODUCT(('Benchmark-Runs'!$X$2:$X$161=A4&"_"&B4)*('Benchmark-Runs'!$W$2:$W$161)^2)/COUNTIF('Benchmark-Runs'!$X$2:$X$161,A4&"_"&B4)-(SUMPRODUCT(('Benchmark-Runs'!$X$2:$X$161=A4&"_"&B4)*('Benchmark-Runs'!$W$2:$W$161))/COUNTIF('Benchmark-Runs'!$X$2:$X$161,A4&"_"&B4))^2),0) -> 0 | G4: =_xlfn.SINGLE(_xlfn.MINIFS('Benchmark-Runs'!$W$2:$W$161,'Benchmark-Runs'!$X$2:$X$161,A4&"_"&B4)) -> 100 | H4: =_xlfn.SINGLE(_xlfn.MAXIFS('Benchmark-Runs'!$W$2:$W$161,'Benchmark-Runs'!$X$2:$X$161,A4&"_"&B4)) -> 100 | I4: =SUMPRODUCT(('Benchmark-Runs'!$X$2:$X$161=A4&"_"&B4)*('Benchmark-Runs'!$F$2:$F$161))/COUNTIF('Benchmark-Runs'!$X$2:$X$161,A4&"_"&B4) -> 0.001412 | J4: =SUMPRODUCT(('Benchmark-Runs'!$X$2:$X$161=A4&"_"&B4)*('Benchmark-Runs'!$F$2:$F$161)) -> 0.00706 | K4: =SUMPRODUCT(('Benchmark-Runs'!$X$2:$X$161=A4&"_"&B4)*('Benchmark-Runs'!$E$2:$E$161))/COUNTIF('Benchmark-Runs'!$X$2:$X$161,A4&"_"&B4) -> 13.176 | L4: =SUMPRODUCT(('Benchmark-Runs'!$X$2:$X$161=A4&"_"&B4)*('Benchmark-Runs'!$I$2:$I$161))/COUNTIF('Benchmark-Runs'!$X$2:$X$161,A4&"_"&B4) -> 7285.4 | M4: =SUMPRODUCT(('Benchmark-Runs'!$X$2:$X$161=A4&"_"&B4)*('Benchmark-Runs'!$G$2:$G$161))/COUNTIF('Benchmark-Runs'!$X$2:$X$161,A4&"_"&B4) -> 6576 | N4: =SUMPRODUCT(('Benchmark-Runs'!$X$2:$X$161=A4&"_"&B4)*('Benchmark-Runs'!$H$2:$H$161))/COUNTIF('Benchmark-Runs'!$X$2:$X$161,A4&"_"&B4) -> 709.4 | O4: =IFERROR(I4/E4,"-") -> 1.412e-05 | P4: =COUNTIF('Benchmark-Runs'!$X$2:$X$161,A4&"_"&B4) -> 5 | Q4: =IFERROR(SUMPRODUCT(('Benchmark-Runs'!$X$2:$X$161=A4&"_"&B4)*('Benchmark-Runs'!$V$2:$V$161))/COUNTIF('Benchmark-Runs'!$X$2:$X$161,A4&"_"&B4),"-") -> 3
A5: gpt-4o-mini | B5: C2_Precision | C5: =_xlfn.XLOOKUP(Tabelle2[[#This Row],[Config]],Tabelle2!$A$1:$A$8,Tabelle2!$B$1:$B$8) -> P6 | D5: =Tabelle2[[#This Row],[Model]] & " | " & Tabelle2[[#This Row],[Spalte2]] -> gpt-4o-mini | P6 | E5: =SUMPRODUCT(('Benchmark-Runs'!$X$2:$X$161=A5&"_"&B5)*('Benchmark-Runs'!$W$2:$W$161))/COUNTIF('Benchmark-Runs'!$X$2:$X$161,A5&"_"&B5) -> 73.333333 | F5: =IFERROR(SQRT(SUMPRODUCT(('Benchmark-Runs'!$X$2:$X$161=A5&"_"&B5)*('Benchmark-Runs'!$W$2:$W$161)^2)/COUNTIF('Benchmark-Runs'!$X$2:$X$161,A5&"_"&B5)-(SUMPRODUCT(('Benchmark-Runs'!$X$2:$X$161=A5&"_"&B5)*('Benchmark-Runs'!$W$2:$W$161))/COUNTIF('Benchmark-Runs'!$X$2:$X$161,A5&"_"&B5))^2),0) -> 13.333333 | G5: =_xlfn.SINGLE(_xlfn.MINIFS('Benchmark-Runs'!$W$2:$W$161,'Benchmark-Runs'!$X$2:$X$161,A5&"_"&B5)) -> 66.666667 | H5: =_xlfn.SINGLE(_xlfn.MAXIFS('Benchmark-Runs'!$W$2:$W$161,'Benchmark-Runs'!$X$2:$X$161,A5&"_"&B5)) -> 100 | I5: =SUMPRODUCT(('Benchmark-Runs'!$X$2:$X$161=A5&"_"&B5)*('Benchmark-Runs'!$F$2:$F$161))/COUNTIF('Benchmark-Runs'!$X$2:$X$161,A5&"_"&B5) -> 0.00139 | J5: =SUMPRODUCT(('Benchmark-Runs'!$X$2:$X$161=A5&"_"&B5)*('Benchmark-Runs'!$F$2:$F$161)) -> 0.00695 | K5: =SUMPRODUCT(('Benchmark-Runs'!$X$2:$X$161=A5&"_"&B5)*('Benchmark-Runs'!$E$2:$E$161))/COUNTIF('Benchmark-Runs'!$X$2:$X$161,A5&"_"&B5) -> 14.016 | L5: =SUMPRODUCT(('Benchmark-Runs'!$X$2:$X$161=A5&"_"&B5)*('Benchmark-Runs'!$I$2:$I$161))/COUNTIF('Benchmark-Runs'!$X$2:$X$161,A5&"_"&B5) -> 7248.6 | M5: =SUMPRODUCT(('Benchmark-Runs'!$X$2:$X$161=A5&"_"&B5)*('Benchmark-Runs'!$G$2:$G$161))/COUNTIF('Benchmark-Runs'!$X$2:$X$161,A5&"_"&B5) -> 6576 | N5: =SUMPRODUCT(('Benchmark-Runs'!$X$2:$X$161=A5&"_"&B5)*('Benchmark-Runs'!$H$2:$H$161))/COUNTIF('Benchmark-Runs'!$X$2:$X$161,A5&"_"&B5) -> 672.6 | O5: =IFERROR(I5/E5,"-") -> 1.8954545e-05 | P5: =COUNTIF('Benchmark-Runs'!$X$2:$X$161,A5&"_"&B5) -> 5 | Q5: =IFERROR(SUMPRODUCT(('Benchmark-Runs'!$X$2:$X$161=A5&"_"&B5)*('Benchmark-Runs'!$V$2:$V$161))/COUNTIF('Benchmark-Runs'!$X$2:$X$161,A5&"_"&B5),"-") -> 3
A6: gpt-4o-mini | B6: C6_BatchOnly | C6: =_xlfn.XLOOKUP(Tabelle2[[#This Row],[Config]],Tabelle2!$A$1:$A$8,Tabelle2!$B$1:$B$8) -> P2 | D6: =Tabelle2[[#This Row],[Model]] & " | " & Tabelle2[[#This Row],[Spalte2]] -> gpt-4o-mini | P2 | E6: =SUMPRODUCT(('Benchmark-Runs'!$X$2:$X$161=A6&"_"&B6)*('Benchmark-Runs'!$W$2:$W$161))/COUNTIF('Benchmark-Runs'!$X$2:$X$161,A6&"_"&B6) -> 100 | F6: =IFERROR(SQRT(SUMPRODUCT(('Benchmark-Runs'!$X$2:$X$161=A6&"_"&B6)*('Benchmark-Runs'!$W$2:$W$161)^2)/COUNTIF('Benchmark-Runs'!$X$2:$X$161,A6&"_"&B6)-(SUMPRODUCT(('Benchmark-Runs'!$X$2:$X$161=A6&"_"&B6)*('Benchmark-Runs'!$W$2:$W$161))/COUNTIF('Benchmark-Runs'!$X$2:$X$161,A6&"_"&B6))^2),0) -> 0 | G6: =_xlfn.SINGLE(_xlfn.MINIFS('Benchmark-Runs'!$W$2:$W$161,'Benchmark-Runs'!$X$2:$X$161,A6&"_"&B6)) -> 100 | H6: =_xlfn.SINGLE(_xlfn.MAXIFS('Benchmark-Runs'!$W$2:$W$161,'Benchmark-Runs'!$X$2:$X$161,A6&"_"&B6)) -> 100 | I6: =SUMPRODUCT(('Benchmark-Runs'!$X$2:$X$161=A6&"_"&B6)*('Benchmark-Runs'!$F$2:$F$161))/COUNTIF('Benchmark-Runs'!$X$2:$X$161,A6&"_"&B6) -> 0.0038786 | J6: =SUMPRODUCT(('Benchmark-Runs'!$X$2:$X$161=A6&"_"&B6)*('Benchmark-Runs'!$F$2:$F$161)) -> 0.019393 | K6: =SUMPRODUCT(('Benchmark-Runs'!$X$2:$X$161=A6&"_"&B6)*('Benchmark-Runs'!$E$2:$E$161))/COUNTIF('Benchmark-Runs'!$X$2:$X$161,A6&"_"&B6) -> 12.966 | L6: =SUMPRODUCT(('Benchmark-Runs'!$X$2:$X$161=A6&"_"&B6)*('Benchmark-Runs'!$I$2:$I$161))/COUNTIF('Benchmark-Runs'!$X$2:$X$161,A6&"_"&B6) -> 23724.8 | M6: =SUMPRODUCT(('Benchmark-Runs'!$X$2:$X$161=A6&"_"&B6)*('Benchmark-Runs'!$G$2:$G$161))/COUNTIF('Benchmark-Runs'!$X$2:$X$161,A6&"_"&B6) -> 23014 | N6: =SUMPRODUCT(('Benchmark-Runs'!$X$2:$X$161=A6&"_"&B6)*('Benchmark-Runs'!$H$2:$H$161))/COUNTIF('Benchmark-Runs'!$X$2:$X$161,A6&"_"&B6) -> 710.8 | O6: =IFERROR(I6/E6,"-") -> 3.8786e-05 | P6: =COUNTIF('Benchmark-Runs'!$X$2:$X$161,A6&"_"&B6) -> 5 | Q6: =IFERROR(SUMPRODUCT(('Benchmark-Runs'!$X$2:$X$161=A6&"_"&B6)*('Benchmark-Runs'!$V$2:$V$161))/COUNTIF('Benchmark-Runs'!$X$2:$X$161,A6&"_"&B6),"-") -> 3
A7: gpt-5-nano | B7: C8_BatchFiltered_NoName | C7: =_xlfn.XLOOKUP(Tabelle2[[#This Row],[Config]],Tabelle2!$A$1:$A$8,Tabelle2!$B$1:$B$8) -> P7 | D7: =Tabelle2[[#This Row],[Model]] & " | " & Tabelle2[[#This Row],[Spalte2]] -> gpt-5-nano | P7 | E7: =SUMPRODUCT(('Benchmark-Runs'!$X$2:$X$161=A7&"_"&B7)*('Benchmark-Runs'!$W$2:$W$161))/COUNTIF('Benchmark-Runs'!$X$2:$X$161,A7&"_"&B7) -> 86.666667 | F7: =IFERROR(SQRT(SUMPRODUCT(('Benchmark-Runs'!$X$2:$X$161=A7&"_"&B7)*('Benchmark-Runs'!$W$2:$W$161)^2)/COUNTIF('Benchmark-Runs'!$X$2:$X$161,A7&"_"&B7)-(SUMPRODUCT(('Benchmark-Runs'!$X$2:$X$161=A7&"_"&B7)*('Benchmark-Runs'!$W$2:$W$161))/COUNTIF('Benchmark-Runs'!$X$2:$X$161,A7&"_"&B7))^2),0) -> 16.329932 | G7: =_xlfn.SINGLE(_xlfn.MINIFS('Benchmark-Runs'!$W$2:$W$161,'Benchmark-Runs'!$X$2:$X$161,A7&"_"&B7)) -> 66.666667 | H7: =_xlfn.SINGLE(_xlfn.MAXIFS('Benchmark-Runs'!$W$2:$W$161,'Benchmark-Runs'!$X$2:$X$161,A7&"_"&B7)) -> 100 | I7: =SUMPRODUCT(('Benchmark-Runs'!$X$2:$X$161=A7&"_"&B7)*('Benchmark-Runs'!$F$2:$F$161))/COUNTIF('Benchmark-Runs'!$X$2:$X$161,A7&"_"&B7) -> 0.0036 | J7: =SUMPRODUCT(('Benchmark-Runs'!$X$2:$X$161=A7&"_"&B7)*('Benchmark-Runs'!$F$2:$F$161)) -> 0.018 | K7: =SUMPRODUCT(('Benchmark-Runs'!$X$2:$X$161=A7&"_"&B7)*('Benchmark-Runs'!$E$2:$E$161))/COUNTIF('Benchmark-Runs'!$X$2:$X$161,A7&"_"&B7) -> 58.114 | L7: =SUMPRODUCT(('Benchmark-Runs'!$X$2:$X$161=A7&"_"&B7)*('Benchmark-Runs'!$I$2:$I$161))/COUNTIF('Benchmark-Runs'!$X$2:$X$161,A7&"_"&B7) -> 12866 | M7: =SUMPRODUCT(('Benchmark-Runs'!$X$2:$X$161=A7&"_"&B7)*('Benchmark-Runs'!$G$2:$G$161))/COUNTIF('Benchmark-Runs'!$X$2:$X$161,A7&"_"&B7) -> 4418 | N7: =SUMPRODUCT(('Benchmark-Runs'!$X$2:$X$161=A7&"_"&B7)*('Benchmark-Runs'!$H$2:$H$161))/COUNTIF('Benchmark-Runs'!$X$2:$X$161,A7&"_"&B7) -> 8448 | O7: =IFERROR(I7/E7,"-") -> 4.1538462e-05 | P7: =COUNTIF('Benchmark-Runs'!$X$2:$X$161,A7&"_"&B7) -> 5 | Q7: =IFERROR(SUMPRODUCT(('Benchmark-Runs'!$X$2:$X$161=A7&"_"&B7)*('Benchmark-Runs'!$V$2:$V$161))/COUNTIF('Benchmark-Runs'!$X$2:$X$161,A7&"_"&B7),"-") -> 3
A8: gpt-4o-mini | B8: C1_Hybrid | C8: =_xlfn.XLOOKUP(Tabelle2[[#This Row],[Config]],Tabelle2!$A$1:$A$8,Tabelle2!$B$1:$B$8) -> P5 | D8: =Tabelle2[[#This Row],[Model]] & " | " & Tabelle2[[#This Row],[Spalte2]] -> gpt-4o-mini | P5 | E8: =SUMPRODUCT(('Benchmark-Runs'!$X$2:$X$161=A8&"_"&B8)*('Benchmark-Runs'!$W$2:$W$161))/COUNTIF('Benchmark-Runs'!$X$2:$X$161,A8&"_"&B8) -> 73.333333 | F8: =IFERROR(SQRT(SUMPRODUCT(('Benchmark-Runs'!$X$2:$X$161=A8&"_"&B8)*('Benchmark-Runs'!$W$2:$W$161)^2)/COUNTIF('Benchmark-Runs'!$X$2:$X$161,A8&"_"&B8)-(SUMPRODUCT(('Benchmark-Runs'!$X$2:$X$161=A8&"_"&B8)*('Benchmark-Runs'!$W$2:$W$161))/COUNTIF('Benchmark-Runs'!$X$2:$X$161,A8&"_"&B8))^2),0) -> 13.333333 | G8: =_xlfn.SINGLE(_xlfn.MINIFS('Benchmark-Runs'!$W$2:$W$161,'Benchmark-Runs'!$X$2:$X$161,A8&"_"&B8)) -> 66.666667 | H8: =_xlfn.SINGLE(_xlfn.MAXIFS('Benchmark-Runs'!$W$2:$W$161,'Benchmark-Runs'!$X$2:$X$161,A8&"_"&B8)) -> 100 | I8: =SUMPRODUCT(('Benchmark-Runs'!$X$2:$X$161=A8&"_"&B8)*('Benchmark-Runs'!$F$2:$F$161))/COUNTIF('Benchmark-Runs'!$X$2:$X$161,A8&"_"&B8) -> 0.0039116 | J8: =SUMPRODUCT(('Benchmark-Runs'!$X$2:$X$161=A8&"_"&B8)*('Benchmark-Runs'!$F$2:$F$161)) -> 0.019558 | K8: =SUMPRODUCT(('Benchmark-Runs'!$X$2:$X$161=A8&"_"&B8)*('Benchmark-Runs'!$E$2:$E$161))/COUNTIF('Benchmark-Runs'!$X$2:$X$161,A8&"_"&B8) -> 14.092 | L8: =SUMPRODUCT(('Benchmark-Runs'!$X$2:$X$161=A8&"_"&B8)*('Benchmark-Runs'!$I$2:$I$161))/COUNTIF('Benchmark-Runs'!$X$2:$X$161,A8&"_"&B8) -> 23779.6 | M8: =SUMPRODUCT(('Benchmark-Runs'!$X$2:$X$161=A8&"_"&B8)*('Benchmark-Runs'!$G$2:$G$161))/COUNTIF('Benchmark-Runs'!$X$2:$X$161,A8&"_"&B8) -> 23014 | N8: =SUMPRODUCT(('Benchmark-Runs'!$X$2:$X$161=A8&"_"&B8)*('Benchmark-Runs'!$H$2:$H$161))/COUNTIF('Benchmark-Runs'!$X$2:$X$161,A8&"_"&B8) -> 765.6 | O8: =IFERROR(I8/E8,"-") -> 5.334e-05 | P8: =COUNTIF('Benchmark-Runs'!$X$2:$X$161,A8&"_"&B8) -> 5 | Q8: =IFERROR(SUMPRODUCT(('Benchmark-Runs'!$X$2:$X$161=A8&"_"&B8)*('Benchmark-Runs'!$V$2:$V$161))/COUNTIF('Benchmark-Runs'!$X$2:$X$161,A8&"_"&B8),"-") -> 3
A9: gpt-5-nano | B9: C6_BatchOnly | C9: =_xlfn.XLOOKUP(Tabelle2[[#This Row],[Config]],Tabelle2!$A$1:$A$8,Tabelle2!$B$1:$B$8) -> P2 | D9: =Tabelle2[[#This Row],[Model]] & " | " & Tabelle2[[#This Row],[Spalte2]] -> gpt-5-nano | P2 | E9: =SUMPRODUCT(('Benchmark-Runs'!$X$2:$X$161=A9&"_"&B9)*('Benchmark-Runs'!$W$2:$W$161))/COUNTIF('Benchmark-Runs'!$X$2:$X$161,A9&"_"&B9) -> 86.666667 | F9: =IFERROR(SQRT(SUMPRODUCT(('Benchmark-Runs'!$X$2:$X$161=A9&"_"&B9)*('Benchmark-Runs'!$W$2:$W$161)^2)/COUNTIF('Benchmark-Runs'!$X$2:$X$161,A9&"_"&B9)-(SUMPRODUCT(('Benchmark-Runs'!$X$2:$X$161=A9&"_"&B9)*('Benchmark-Runs'!$W$2:$W$161))/COUNTIF('Benchmark-Runs'!$X$2:$X$161,A9&"_"&B9))^2),0) -> 16.329932 | G9: =_xlfn.SINGLE(_xlfn.MINIFS('Benchmark-Runs'!$W$2:$W$161,'Benchmark-Runs'!$X$2:$X$161,A9&"_"&B9)) -> 66.666667 | H9: =_xlfn.SINGLE(_xlfn.MAXIFS('Benchmark-Runs'!$W$2:$W$161,'Benchmark-Runs'!$X$2:$X$161,A9&"_"&B9)) -> 100 | I9: =SUMPRODUCT(('Benchmark-Runs'!$X$2:$X$161=A9&"_"&B9)*('Benchmark-Runs'!$F$2:$F$161))/COUNTIF('Benchmark-Runs'!$X$2:$X$161,A9&"_"&B9) -> 0.0047094 | J9: =SUMPRODUCT(('Benchmark-Runs'!$X$2:$X$161=A9&"_"&B9)*('Benchmark-Runs'!$F$2:$F$161)) -> 0.023547 | K9: =SUMPRODUCT(('Benchmark-Runs'!$X$2:$X$161=A9&"_"&B9)*('Benchmark-Runs'!$E$2:$E$161))/COUNTIF('Benchmark-Runs'!$X$2:$X$161,A9&"_"&B9) -> 59.898 | L9: =SUMPRODUCT(('Benchmark-Runs'!$X$2:$X$161=A9&"_"&B9)*('Benchmark-Runs'!$I$2:$I$161))/COUNTIF('Benchmark-Runs'!$X$2:$X$161,A9&"_"&B9) -> 31910.4 | M9: =SUMPRODUCT(('Benchmark-Runs'!$X$2:$X$161=A9&"_"&B9)*('Benchmark-Runs'!$G$2:$G$161))/COUNTIF('Benchmark-Runs'!$X$2:$X$161,A9&"_"&B9) -> 23013 | N9: =SUMPRODUCT(('Benchmark-Runs'!$X$2:$X$161=A9&"_"&B9)*('Benchmark-Runs'!$H$2:$H$161))/COUNTIF('Benchmark-Runs'!$X$2:$X$161,A9&"_"&B9) -> 8897.4 | O9: =IFERROR(I9/E9,"-") -> 5.4339231e-05 | P9: =COUNTIF('Benchmark-Runs'!$X$2:$X$161,A9&"_"&B9) -> 5 | Q9: =IFERROR(SUMPRODUCT(('Benchmark-Runs'!$X$2:$X$161=A9&"_"&B9)*('Benchmark-Runs'!$V$2:$V$161))/COUNTIF('Benchmark-Runs'!$X$2:$X$161,A9&"_"&B9),"-") -> 3
A10: gpt-5-nano | B10: C5_BatchFiltered | C10: =_xlfn.XLOOKUP(Tabelle2[[#This Row],[Config]],Tabelle2!$A$1:$A$8,Tabelle2!$B$1:$B$8) -> P8 | D10: =Tabelle2[[#This Row],[Model]] & " | " & Tabelle2[[#This Row],[Spalte2]] -> gpt-5-nano | P8 | E10: =SUMPRODUCT(('Benchmark-Runs'!$X$2:$X$161=A10&"_"&B10)*('Benchmark-Runs'!$W$2:$W$161))/COUNTIF('Benchmark-Runs'!$X$2:$X$161,A10&"_"&B10) -> 66.666667 | F10: =IFERROR(SQRT(SUMPRODUCT(('Benchmark-Runs'!$X$2:$X$161=A10&"_"&B10)*('Benchmark-Runs'!$W$2:$W$161)^2)/COUNTIF('Benchmark-Runs'!$X$2:$X$161,A10&"_"&B10)-(SUMPRODUCT(('Benchmark-Runs'!$X$2:$X$161=A10&"_"&B10)*('Benchmark-Runs'!$W$2:$W$161))/COUNTIF('Benchmark-Runs'!$X$2:$X$161,A10&"_"&B10))^2),0) -> 21.081851 | G10: =_xlfn.SINGLE(_xlfn.MINIFS('Benchmark-Runs'!$W$2:$W$161,'Benchmark-Runs'!$X$2:$X$161,A10&"_"&B10)) -> 33.333333 | H10: =_xlfn.SINGLE(_xlfn.MAXIFS('Benchmark-Runs'!$W$2:$W$161,'Benchmark-Runs'!$X$2:$X$161,A10&"_"&B10)) -> 100 | I10: =SUMPRODUCT(('Benchmark-Runs'!$X$2:$X$161=A10&"_"&B10)*('Benchmark-Runs'!$F$2:$F$161))/COUNTIF('Benchmark-Runs'!$X$2:$X$161,A10&"_"&B10) -> 0.0048608 | J10: =SUMPRODUCT(('Benchmark-Runs'!$X$2:$X$161=A10&"_"&B10)*('Benchmark-Runs'!$F$2:$F$161)) -> 0.024304 | K10: =SUMPRODUCT(('Benchmark-Runs'!$X$2:$X$161=A10&"_"&B10)*('Benchmark-Runs'!$E$2:$E$161))/COUNTIF('Benchmark-Runs'!$X$2:$X$161,A10&"_"&B10) -> 124.666 | L10: =SUMPRODUCT(('Benchmark-Runs'!$X$2:$X$161=A10&"_"&B10)*('Benchmark-Runs'!$I$2:$I$161))/COUNTIF('Benchmark-Runs'!$X$2:$X$161,A10&"_"&B10) -> 16017.8 | M10: =SUMPRODUCT(('Benchmark-Runs'!$X$2:$X$161=A10&"_"&B10)*('Benchmark-Runs'!$G$2:$G$161))/COUNTIF('Benchmark-Runs'!$X$2:$X$161,A10&"_"&B10) -> 4418 | N10: =SUMPRODUCT(('Benchmark-Runs'!$X$2:$X$161=A10&"_"&B10)*('Benchmark-Runs'!$H$2:$H$161))/COUNTIF('Benchmark-Runs'!$X$2:$X$161,A10&"_"&B10) -> 11599.8 | O10: =IFERROR(I10/E10,"-") -> 7.2912e-05 | P10: =COUNTIF('Benchmark-Runs'!$X$2:$X$161,A10&"_"&B10) -> 5 | Q10: =IFERROR(SUMPRODUCT(('Benchmark-Runs'!$X$2:$X$161=A10&"_"&B10)*('Benchmark-Runs'!$V$2:$V$161))/COUNTIF('Benchmark-Runs'!$X$2:$X$161,A10&"_"&B10),"-") -> 3
A11: gpt-5-nano | B11: C1_Hybrid | C11: =_xlfn.XLOOKUP(Tabelle2[[#This Row],[Config]],Tabelle2!$A$1:$A$8,Tabelle2!$B$1:$B$8) -> P5 | D11: =Tabelle2[[#This Row],[Model]] & " | " & Tabelle2[[#This Row],[Spalte2]] -> gpt-5-nano | P5 | E11: =SUMPRODUCT(('Benchmark-Runs'!$X$2:$X$161=A11&"_"&B11)*('Benchmark-Runs'!$W$2:$W$161))/COUNTIF('Benchmark-Runs'!$X$2:$X$161,A11&"_"&B11) -> 53.333333 | F11: =IFERROR(SQRT(SUMPRODUCT(('Benchmark-Runs'!$X$2:$X$161=A11&"_"&B11)*('Benchmark-Runs'!$W$2:$W$161)^2)/COUNTIF('Benchmark-Runs'!$X$2:$X$161,A11&"_"&B11)-(SUMPRODUCT(('Benchmark-Runs'!$X$2:$X$161=A11&"_"&B11)*('Benchmark-Runs'!$W$2:$W$161))/COUNTIF('Benchmark-Runs'!$X$2:$X$161,A11&"_"&B11))^2),0) -> 16.329932 | G11: =_xlfn.SINGLE(_xlfn.MINIFS('Benchmark-Runs'!$W$2:$W$161,'Benchmark-Runs'!$X$2:$X$161,A11&"_"&B11)) -> 33.333333 | H11: =_xlfn.SINGLE(_xlfn.MAXIFS('Benchmark-Runs'!$W$2:$W$161,'Benchmark-Runs'!$X$2:$X$161,A11&"_"&B11)) -> 66.666667 | I11: =SUMPRODUCT(('Benchmark-Runs'!$X$2:$X$161=A11&"_"&B11)*('Benchmark-Runs'!$F$2:$F$161))/COUNTIF('Benchmark-Runs'!$X$2:$X$161,A11&"_"&B11) -> 0.0054664 | J11: =SUMPRODUCT(('Benchmark-Runs'!$X$2:$X$161=A11&"_"&B11)*('Benchmark-Runs'!$F$2:$F$161)) -> 0.027332 | K11: =SUMPRODUCT(('Benchmark-Runs'!$X$2:$X$161=A11&"_"&B11)*('Benchmark-Runs'!$E$2:$E$161))/COUNTIF('Benchmark-Runs'!$X$2:$X$161,A11&"_"&B11) -> 147.836 | L11: =SUMPRODUCT(('Benchmark-Runs'!$X$2:$X$161=A11&"_"&B11)*('Benchmark-Runs'!$I$2:$I$161))/COUNTIF('Benchmark-Runs'!$X$2:$X$161,A11&"_"&B11) -> 33802.6 | M11: =SUMPRODUCT(('Benchmark-Runs'!$X$2:$X$161=A11&"_"&B11)*('Benchmark-Runs'!$G$2:$G$161))/COUNTIF('Benchmark-Runs'!$X$2:$X$161,A11&"_"&B11) -> 23013 | N11: =SUMPRODUCT(('Benchmark-Runs'!$X$2:$X$161=A11&"_"&B11)*('Benchmark-Runs'!$H$2:$H$161))/COUNTIF('Benchmark-Runs'!$X$2:$X$161,A11&"_"&B11) -> 10789.6 | O11: =IFERROR(I11/E11,"-") -> 0.000102495 | P11: =COUNTIF('Benchmark-Runs'!$X$2:$X$161,A11&"_"&B11) -> 5 | Q11: =IFERROR(SUMPRODUCT(('Benchmark-Runs'!$X$2:$X$161=A11&"_"&B11)*('Benchmark-Runs'!$V$2:$V$161))/COUNTIF('Benchmark-Runs'!$X$2:$X$161,A11&"_"&B11),"-") -> 3
A12: gpt-5-nano | B12: C7_FilterOnly | C12: =_xlfn.XLOOKUP(Tabelle2[[#This Row],[Config]],Tabelle2!$A$1:$A$8,Tabelle2!$B$1:$B$8) -> P3 | D12: =Tabelle2[[#This Row],[Model]] & " | " & Tabelle2[[#This Row],[Spalte2]] -> gpt-5-nano | P3 | E12: =SUMPRODUCT(('Benchmark-Runs'!$X$2:$X$161=A12&"_"&B12)*('Benchmark-Runs'!$W$2:$W$161))/COUNTIF('Benchmark-Runs'!$X$2:$X$161,A12&"_"&B12) -> 80 | F12: =IFERROR(SQRT(SUMPRODUCT(('Benchmark-Runs'!$X$2:$X$161=A12&"_"&B12)*('Benchmark-Runs'!$W$2:$W$161)^2)/COUNTIF('Benchmark-Runs'!$X$2:$X$161,A12&"_"&B12)-(SUMPRODUCT(('Benchmark-Runs'!$X$2:$X$161=A12&"_"&B12)*('Benchmark-Runs'!$W$2:$W$161))/COUNTIF('Benchmark-Runs'!$X$2:$X$161,A12&"_"&B12))^2),0) -> 26.666667 | G12: =_xlfn.SINGLE(_xlfn.MINIFS('Benchmark-Runs'!$W$2:$W$161,'Benchmark-Runs'!$X$2:$X$161,A12&"_"&B12)) -> 33.333333 | H12: =_xlfn.SINGLE(_xlfn.MAXIFS('Benchmark-Runs'!$W$2:$W$161,'Benchmark-Runs'!$X$2:$X$161,A12&"_"&B12)) -> 100 | I12: =SUMPRODUCT(('Benchmark-Runs'!$X$2:$X$161=A12&"_"&B12)*('Benchmark-Runs'!$F$2:$F$161))/COUNTIF('Benchmark-Runs'!$X$2:$X$161,A12&"_"&B12) -> 0.0091776 | J12: =SUMPRODUCT(('Benchmark-Runs'!$X$2:$X$161=A12&"_"&B12)*('Benchmark-Runs'!$F$2:$F$161)) -> 0.045888 | K12: =SUMPRODUCT(('Benchmark-Runs'!$X$2:$X$161=A12&"_"&B12)*('Benchmark-Runs'!$E$2:$E$161))/COUNTIF('Benchmark-Runs'!$X$2:$X$161,A12&"_"&B12) -> 176.254 | L12: =SUMPRODUCT(('Benchmark-Runs'!$X$2:$X$161=A12&"_"&B12)*('Benchmark-Runs'!$I$2:$I$161))/COUNTIF('Benchmark-Runs'!$X$2:$X$161,A12&"_"&B12) -> 28693.6 | M12: =SUMPRODUCT(('Benchmark-Runs'!$X$2:$X$161=A12&"_"&B12)*('Benchmark-Runs'!$G$2:$G$161))/COUNTIF('Benchmark-Runs'!$X$2:$X$161,A12&"_"&B12) -> 6571 | N12: =SUMPRODUCT(('Benchmark-Runs'!$X$2:$X$161=A12&"_"&B12)*('Benchmark-Runs'!$H$2:$H$161))/COUNTIF('Benchmark-Runs'!$X$2:$X$161,A12&"_"&B12) -> 22122.6 | O12: =IFERROR(I12/E12,"-") -> 0.00011472 | P12: =COUNTIF('Benchmark-Runs'!$X$2:$X$161,A12&"_"&B12) -> 5 | Q12: =IFERROR(SUMPRODUCT(('Benchmark-Runs'!$X$2:$X$161=A12&"_"&B12)*('Benchmark-Runs'!$V$2:$V$161))/COUNTIF('Benchmark-Runs'!$X$2:$X$161,A12&"_"&B12),"-") -> 3
A13: gpt-5-nano | B13: C2_Precision | C13: =_xlfn.XLOOKUP(Tabelle2[[#This Row],[Config]],Tabelle2!$A$1:$A$8,Tabelle2!$B$1:$B$8) -> P6 | D13: =Tabelle2[[#This Row],[Model]] & " | " & Tabelle2[[#This Row],[Spalte2]] -> gpt-5-nano | P6 | E13: =SUMPRODUCT(('Benchmark-Runs'!$X$2:$X$161=A13&"_"&B13)*('Benchmark-Runs'!$W$2:$W$161))/COUNTIF('Benchmark-Runs'!$X$2:$X$161,A13&"_"&B13) -> 66.666667 | F13: =IFERROR(SQRT(SUMPRODUCT(('Benchmark-Runs'!$X$2:$X$161=A13&"_"&B13)*('Benchmark-Runs'!$W$2:$W$161)^2)/COUNTIF('Benchmark-Runs'!$X$2:$X$161,A13&"_"&B13)-(SUMPRODUCT(('Benchmark-Runs'!$X$2:$X$161=A13&"_"&B13)*('Benchmark-Runs'!$W$2:$W$161))/COUNTIF('Benchmark-Runs'!$X$2:$X$161,A13&"_"&B13))^2),0) -> 0 | G13: =_xlfn.SINGLE(_xlfn.MINIFS('Benchmark-Runs'!$W$2:$W$161,'Benchmark-Runs'!$X$2:$X$161,A13&"_"&B13)) -> 66.666667 | H13: =_xlfn.SINGLE(_xlfn.MAXIFS('Benchmark-Runs'!$W$2:$W$161,'Benchmark-Runs'!$X$2:$X$161,A13&"_"&B13)) -> 66.666667 | I13: =SUMPRODUCT(('Benchmark-Runs'!$X$2:$X$161=A13&"_"&B13)*('Benchmark-Runs'!$F$2:$F$161))/COUNTIF('Benchmark-Runs'!$X$2:$X$161,A13&"_"&B13) -> 0.008682 | J13: =SUMPRODUCT(('Benchmark-Runs'!$X$2:$X$161=A13&"_"&B13)*('Benchmark-Runs'!$F$2:$F$161)) -> 0.04341 | K13: =SUMPRODUCT(('Benchmark-Runs'!$X$2:$X$161=A13&"_"&B13)*('Benchmark-Runs'!$E$2:$E$161))/COUNTIF('Benchmark-Runs'!$X$2:$X$161,A13&"_"&B13) -> 197.204 | L13: =SUMPRODUCT(('Benchmark-Runs'!$X$2:$X$161=A13&"_"&B13)*('Benchmark-Runs'!$I$2:$I$161))/COUNTIF('Benchmark-Runs'!$X$2:$X$161,A13&"_"&B13) -> 27454.8 | M13: =SUMPRODUCT(('Benchmark-Runs'!$X$2:$X$161=A13&"_"&B13)*('Benchmark-Runs'!$G$2:$G$161))/COUNTIF('Benchmark-Runs'!$X$2:$X$161,A13&"_"&B13) -> 6571 | N13: =SUMPRODUCT(('Benchmark-Runs'!$X$2:$X$161=A13&"_"&B13)*('Benchmark-Runs'!$H$2:$H$161))/COUNTIF('Benchmark-Runs'!$X$2:$X$161,A13&"_"&B13) -> 20883.8 | O13: =IFERROR(I13/E13,"-") -> 0.00013023 | P13: =COUNTIF('Benchmark-Runs'!$X$2:$X$161,A13&"_"&B13) -> 5 | Q13: =IFERROR(SUMPRODUCT(('Benchmark-Runs'!$X$2:$X$161=A13&"_"&B13)*('Benchmark-Runs'!$V$2:$V$161))/COUNTIF('Benchmark-Runs'!$X$2:$X$161,A13&"_"&B13),"-") -> 3
... A33: gpt-5.2-chat | B33: C3_Single | C33: =_xlfn.XLOOKUP(Tabelle2[[#This Row],[Config]],Tabelle2!$A$1:$A$8,Tabelle2!$B$1:$B$8) -> P4 | D33: =Tabelle2[[#This Row],[Model]] & " | " & Tabelle2[[#This Row],[Spalte2]] -> gpt-5.2-chat | P4 | E33: =SUMPRODUCT(('Benchmark-Runs'!$X$2:$X$161=A33&"_"&B33)*('Benchmark-Runs'!$W$2:$W$161))/COUNTIF('Benchmark-Runs'!$X$2:$X$161,A33&"_"&B33) -> 66.666667 | F33: =IFERROR(SQRT(SUMPRODUCT(('Benchmark-Runs'!$X$2:$X$161=A33&"_"&B33)*('Benchmark-Runs'!$W$2:$W$161)^2)/COUNTIF('Benchmark-Runs'!$X$2:$X$161,A33&"_"&B33)-(SUMPRODUCT(('Benchmark-Runs'!$X$2:$X$161=A33&"_"&B33)*('Benchmark-Runs'!$W$2:$W$161))/COUNTIF('Benchmark-Runs'!$X$2:$X$161,A33&"_"&B33))^2),0) -> 0 | G33: =_xlfn.SINGLE(_xlfn.MINIFS('Benchmark-Runs'!$W$2:$W$161,'Benchmark-Runs'!$X$2:$X$161,A33&"_"&B33)) -> 66.666667 | H33: =_xlfn.SINGLE(_xlfn.MAXIFS('Benchmark-Runs'!$W$2:$W$161,'Benchmark-Runs'!$X$2:$X$161,A33&"_"&B33)) -> 66.666667 | I33: =SUMPRODUCT(('Benchmark-Runs'!$X$2:$X$161=A33&"_"&B33)*('Benchmark-Runs'!$F$2:$F$161))/COUNTIF('Benchmark-Runs'!$X$2:$X$161,A33&"_"&B33) -> 0.220264 | J33: =SUMPRODUCT(('Benchmark-Runs'!$X$2:$X$161=A33&"_"&B33)*('Benchmark-Runs'!$F$2:$F$161)) -> 1.10132 | K33: =SUMPRODUCT(('Benchmark-Runs'!$X$2:$X$161=A33&"_"&B33)*('Benchmark-Runs'!$E$2:$E$161))/COUNTIF('Benchmark-Runs'!$X$2:$X$161,A33&"_"&B33) -> 40.35 | L33: =SUMPRODUCT(('Benchmark-Runs'!$X$2:$X$161=A33&"_"&B33)*('Benchmark-Runs'!$I$2:$I$161))/COUNTIF('Benchmark-Runs'!$X$2:$X$161,A33&"_"&B33) -> 113776 | M33: =SUMPRODUCT(('Benchmark-Runs'!$X$2:$X$161=A33&"_"&B33)*('Benchmark-Runs'!$G$2:$G$161))/COUNTIF('Benchmark-Runs'!$X$2:$X$161,A33&"_"&B33) -> 112049 | N33: =SUMPRODUCT(('Benchmark-Runs'!$X$2:$X$161=A33&"_"&B33)*('Benchmark-Runs'!$H$2:$H$161))/COUNTIF('Benchmark-Runs'!$X$2:$X$161,A33&"_"&B33) -> 1727 | O33: =IFERROR(I33/E33,"-") -> 0.00330396 | P33: =COUNTIF('Benchmark-Runs'!$X$2:$X$161,A33&"_"&B33) -> 5 | Q33: =IFERROR(SUMPRODUCT(('Benchmark-Runs'!$X$2:$X$161=A33&"_"&B33)*('Benchmark-Runs'!$V$2:$V$161))/COUNTIF('Benchmark-Runs'!$X$2:$X$161,A33&"_"&B33),"-") -> 3

Sheet Tabelle2
A1: C4_Baseline | B1: P1
A2: C6_BatchOnly | B2: P2
A3: C7_FilterOnly | B3: P3
A4: C3_Single | B4: P4
A5: C1_Hybrid | B5: P5
A6: C2_Precision | B6: P6
A7: C8_BatchFiltered_NoName | B7: P7
A8: C5_BatchFiltered | B8: P8

Sheet Visualization
B2: Config | C2: gpt-4o-mini | D2: gpt-5-nano | E2: gpt-5-chat | F2: gpt-5.2-chat
B3: P1 | C3: 100 | D3: 100 | E3: 100 | F3: 100
B4: P2 | C4: 100 | D4: 86.7 | E4: 100 | F4: 100
B5: P3 | C5: 100 | D5: 80 | E5: 100 | F5: 100
B6: P4 | C6: 86.7 | D6: 60 | E6: 66.7 | F6: 66.7
B7: P5 | C7: 73.3 | D7: 53.3 | E7: 66.7 | F7: 66.7
B8: P6 | C8: 73.3 | D8: 66.7 | E8: 73.3 | F8: 93.3
B9: P7 | C9: 80 | D9: 86.7 | E9: 100 | F9: 93.3
B10: P8 | C10: 66.7 | D10: 66.7 | E10: 66.7 | F10: 53.3
A13: Kosten pro | C13: 1000 | D13: Aufrufe
C15: Acc | D15: Cost per 1000 | E15: D/C
A16: ='★ Ablation-Study'!D2 -> gpt-4o-mini | P7 | C16: ='★ Ablation-Study'!E2 -> 80 | D16: ='★ Ablation-Study'!I2*$C$13 -> 0.9244 | E16: =D16/C16 -> 0.011555
A17: ='★ Ablation-Study'!D3 -> gpt-4o-mini | P8 | C17: ='★ Ablation-Study'!E3 -> 66.666667 | D17: ='★ Ablation-Study'!I3*$C$13 -> 0.941 | E17: =D17/C17 -> 0.014115
A18: ='★ Ablation-Study'!D4 -> gpt-4o-mini | P3 | C18: ='★ Ablation-Study'!E4 -> 100 | D18: ='★ Ablation-Study'!I4*$C$13 -> 1.412 | E18: =D18/C18 -> 0.01412
A19: ='★ Ablation-Study'!D5 -> gpt-4o-mini | P6 | C19: ='★ Ablation-Study'!E5 -> 73.333333 | D19: ='★ Ablation-Study'!I5*$C$13 -> 1.39 | E19: =D19/C19 -> 0.018954545
A20: ='★ Ablation-Study'!D6 -> gpt-4o-mini | P2 | C20: ='★ Ablation-Study'!E6 -> 100 | D20: ='★ Ablation-Study'!I6*$C$13 -> 3.8786 | E20: =D20/C20 -> 0.038786
A21: ='★ Ablation-Study'!D7 -> gpt-5-nano | P7 | C21: ='★ Ablation-Study'!E7 -> 86.666667 | D21: ='★ Ablation-Study'!I7*$C$13 -> 3.6 | E21: =D21/C21 -> 0.041538462
A22: ='★ Ablation-Study'!D8 -> gpt-4o-mini | P5 | C22: ='★ Ablation-Study'!E8 -> 73.333333 | D22: ='★ Ablation-Study'!I8*$C$13 -> 3.9116 | E22: =D22/C22 -> 0.05334
A23: ='★ Ablation-Study'!D9 -> gpt-5-nano | P2 | C23: ='★ Ablation-Study'!E9 -> 86.666667 | D23: ='★ Ablation-Study'!I9*$C$13 -> 4.7094 | E23: =D23/C23 -> 0.054339231
A24: ='★ Ablation-Study'!D10 -> gpt-5-nano | P8 | C24: ='★ Ablation-Study'!E10 -> 66.666667 | D24: ='★ Ablation-Study'!I10*$C$13 -> 4.8608 | E24: =D24/C24 -> 0.072912
A25: ='★ Ablation-Study'!D11 -> gpt-5-nano | P5 | C25: ='★ Ablation-Study'!E11 -> 53.333333 | D25: ='★ Ablation-Study'!I11*$C$13 -> 5.4664 | E25: =D25/C25 -> 0.102495
A26: ='★ Ablation-Study'!D12 -> gpt-5-nano | P3 | C26: ='★ Ablation-Study'!E12 -> 80 | D26: ='★ Ablation-Study'!I12*$C$13 -> 9.1776 | E26: =D26/C26 -> 0.11472
A27: ='★ Ablation-Study'!D13 -> gpt-5-nano | P6 | C27: ='★ Ablation-Study'!E13 -> 66.666667 | D27: ='★ Ablation-Study'!I13*$C$13 -> 8.682 | E27: =D27/C27 -> 0.13023
... A47: ='★ Ablation-Study'!D33 -> gpt-5.2-chat | P4 | C47: ='★ Ablation-Study'!E33 -> 66.666667 | D47: ='★ Ablation-Study'!I33*$C$13 -> 220.264 | E47: =D47/C47 -> 3.30396

Sheet ★ Empfehlungen
A1: Kriterium | B1: Model | C1: Config | D1: Accuracy [%] | E1: Cost [USD] | F1: Duration [s]
A2: 🎯 Höchste Accuracy | B2: =IFERROR(INDEX('★ Ablation-Study'!$A$2:$A$33,MATCH(MAX('★ Ablation-Study'!$E$2:$E$33),'★ Ablation-Study'!$E$2:$E$33,0)),"-") -> gpt-4o-mini | C2: =IFERROR(INDEX('★ Ablation-Study'!$B$2:$B$33,MATCH(MAX('★ Ablation-Study'!$E$2:$E$33),'★ Ablation-Study'!$E$2:$E$33,0)),"-") -> C7_FilterOnly | D2: =IFERROR(INDEX('★ Ablation-Study'!$E$2:$E$33,MATCH(MAX('★ Ablation-Study'!$E$2:$E$33),'★ Ablation-Study'!$E$2:$E$33,0)),"-") -> 100 | E2: =IFERROR(INDEX('★ Ablation-Study'!$I$2:$I$33,MATCH(MAX('★ Ablation-Study'!$E$2:$E$33),'★ Ablation-Study'!$E$2:$E$33,0)),"-") -> 0.001412 | F2: =IFERROR(INDEX('★ Ablation-Study'!$K$2:$K$33,MATCH(MAX('★ Ablation-Study'!$E$2:$E$33),'★ Ablation-Study'!$E$2:$E$33,0)),"-") -> 13.176
A3: 💰 Niedrigste Kosten | B3: =IFERROR(INDEX('★ Ablation-Study'!$A$2:$A$33,MATCH(MIN('★ Ablation-Study'!$I$2:$I$33),'★ Ablation-Study'!$I$2:$I$33,0)),"-") -> gpt-4o-mini | C3: =IFERROR(INDEX('★ Ablation-Study'!$B$2:$B$33,MATCH(MIN('★ Ablation-Study'!$I$2:$I$33),'★ Ablation-Study'!$I$2:$I$33,0)),"-") -> C8_BatchFiltered_NoName | D3: =IFERROR(INDEX('★ Ablation-Study'!$E$2:$E$33,MATCH(MIN('★ Ablation-Study'!$I$2:$I$33),'★ Ablation-Study'!$I$2:$I$33,0)),"-") -> 80 | E3: =IFERROR(INDEX('★ Ablation-Study'!$I$2:$I$33,MATCH(MIN('★ Ablation-Study'!$I$2:$I$33),'★ Ablation-Study'!$I$2:$I$33,0)),"-") -> 0.0009244 | F3: =IFERROR(INDEX('★ Ablation-Study'!$K$2:$K$33,MATCH(MIN('★ Ablation-Study'!$I$2:$I$33),'★ Ablation-Study'!$I$2:$I$33,0)),"-") -> 9.282
A4: ⚡ Schnellste | B4: =IFERROR(INDEX('★ Ablation-Study'!$A$2:$A$33,MATCH(MIN('★ Ablation-Study'!$K$2:$K$33),'★ Ablation-Study'!$K$2:$K$33,0)),"-") -> gpt-4o-mini | C4: =IFERROR(INDEX('★ Ablation-Study'!$B$2:$B$33,MATCH(MIN('★ Ablation-Study'!$K$2:$K$33),'★ Ablation-Study'!$K$2:$K$33,0)),"-") -> C5_BatchFiltered | D4: =IFERROR(INDEX('★ Ablation-Study'!$E$2:$E$33,MATCH(MIN('★ Ablation-Study'!$K$2:$K$33),'★ Ablation-Study'!$K$2:$K$33,0)),"-") -> 66.666667 | E4: =IFERROR(INDEX('★ Ablation-Study'!$I$2:$I$33,MATCH(MIN('★ Ablation-Study'!$K$2:$K$33),'★ Ablation-Study'!$K$2:$K$33,0)),"-") -> 0.000941 | F4: =IFERROR(INDEX('★ Ablation-Study'!$K$2:$K$33,MATCH(MIN('★ Ablation-Study'!$K$2:$K$33),'★ Ablation-Study'!$K$2:$K$33,0)),"-") -> 8.8
A5: ⚖️ Beste Kosten-Effizienz | B5: =IFERROR(INDEX('★ Ablation-Study'!$A$2:$A$33,MATCH(MIN('★ Ablation-Study'!$O$2:$O$33),'★ Ablation-Study'!$O$2:$O$33,0)),"-") -> gpt-4o-mini | C5: =IFERROR(INDEX('★ Ablation-Study'!$B$2:$B$33,MATCH(MIN('★ Ablation-Study'!$O$2:$O$33),'★ Ablation-Study'!$O$2:$O$33,0)),"-") -> C8_BatchFiltered_NoName | D5: =IFERROR(INDEX('★ Ablation-Study'!$E$2:$E$33,MATCH(MIN('★ Ablation-Study'!$O$2:$O$33),'★ Ablation-Study'!$O$2:$O$33,0)),"-") -> 80 | E5: =IFERROR(INDEX('★ Ablation-Study'!$I$2:$I$33,MATCH(MIN('★ Ablation-Study'!$O$2:$O$33),'★ Ablation-Study'!$O$2:$O$33,0)),"-") -> 0.0009244 | F5: =IFERROR(INDEX('★ Ablation-Study'!$K$2:$K$33,MATCH(MIN('★ Ablation-Study'!$O$2:$O$33),'★ Ablation-Study'!$O$2:$O$33,0)),"-") -> 9.282

Sheet Ground-Truth
A1: Position | B1: Schicht | C1: Auswerten | D1: Korrekte_EPD_ID | E1: Vorschlag (häufigster Match) | F1: Anmerkung
A2: 1 | B2: Deckschicht | C2: Ja | D2: 864 | E2: 864
A3: 2 | B3: Binderschicht | C3: Ja | D3: 38 | E3: 38
A4: 3 | B4: Tragschicht | C4: Ja | D4: 39 | E4: 39
A5: 4 | B5: Schottertrag | C5: Nein | E5: 39
A6: 5 | B6: Frostschutzschicht | C6: Nein | E6: 839

Sheet Benchmark-Runs
A1: Report | B1: Config | C1: Model | D1: Run # | E1: Duration [s] | F1: Cost [USD] | G1: Input Tokens | H1: Output Tokens | I1: Total Tokens | J1: API Calls | K1: Top Match 1 | L1: Top Match 2 | M1: Top Match 3 | N1: Top Match 4 | O1: Top Match 5 | P1: Pos1 Correct | Q1: Pos2 Correct | R1: Pos3 Correct | S1: Pos4 Correct | T1: Pos5 Correct | U1: Correct Count | V1: Evaluated Count | W1: Accuracy [%] | X1: Model_Config
A2: full_benchmark_report1.json | B2: C1_Hybrid | C2: gpt-4o-mini | D2: 1 | E2: 16.46 | F2: 0.003948 | G2: 23014 | H2: 826 | I2: =G2+H2 -> 23840 | J2: 1 | K2: 934 | L2: 38 | M2: 39 | N2: 39 | O2: 839 | P2: =IF(OR('Ground-Truth'!$C$2<>"Ja",'Ground-Truth'!$D$2=""),"",IF(TEXT(K2,"0")=TEXT('Ground-Truth'!$D$2,"0"),1,0)) -> 0 | Q2: =IF(OR('Ground-Truth'!$C$3<>"Ja",'Ground-Truth'!$D$3=""),"",IF(TEXT(L2,"0")=TEXT('Ground-Truth'!$D$3,"0"),1,0)) -> 1 | R2: =IF(OR('Ground-Truth'!$C$4<>"Ja",'Ground-Truth'!$D$4=""),"",IF(TEXT(M2,"0")=TEXT('Ground-Truth'!$D$4,"0"),1,0)) -> 1 | S2: =IF(OR('Ground-Truth'!$C$5<>"Ja",'Ground-Truth'!$D$5=""),"",IF(TEXT(N2,"0")=TEXT('Ground-Truth'!$D$5,"0"),1,0)) | T2: =IF(OR('Ground-Truth'!$C$6<>"Ja",'Ground-Truth'!$D$6=""),"",IF(TEXT(O2,"0")=TEXT('Ground-Truth'!$D$6,"0"),1,0)) | U2: =SUM(P2:T2) -> 2 | V2: =COUNT(P2:T2) -> 3 | W2: =IF(V2=0,0,U2/V2*100) -> 66.666667 | X2: =C2&"_"&B2 -> gpt-4o-mini_C1_Hybrid
A3: full_benchmark_report1.json | B3: C1_Hybrid | C3: gpt-4o-mini | D3: 2 | E3: 14.24 | F3: 0.003966 | G3: 23014 | H3: 856 | I3: =G3+H3 -> 23870 | J3: 1 | K3: 864 | L3: 38 | M3: 39 | N3: 39 | O3: 839 | P3: =IF(OR('Ground-Truth'!$C$2<>"Ja",'Ground-Truth'!$D$2=""),"",IF(TEXT(K3,"0")=TEXT('Ground-Truth'!$D$2,"0"),1,0)) -> 1 | Q3: =IF(OR('Ground-Truth'!$C$3<>"Ja",'Ground-Truth'!$D$3=""),"",IF(TEXT(L3,"0")=TEXT('Ground-Truth'!$D$3,"0"),1,0)) -> 1 | R3: =IF(OR('Ground-Truth'!$C$4<>"Ja",'Ground-Truth'!$D$4=""),"",IF(TEXT(M3,"0")=TEXT('Ground-Truth'!$D$4,"0"),1,0)) -> 1 | S3: =IF(OR('Ground-Truth'!$C$5<>"Ja",'Ground-Truth'!$D$5=""),"",IF(TEXT(N3,"0")=TEXT('Ground-Truth'!$D$5,"0"),1,0)) | T3: =IF(OR('Ground-Truth'!$C$6<>"Ja",'Ground-Truth'!$D$6=""),"",IF(TEXT(O3,"0")=TEXT('Ground-Truth'!$D$6,"0"),1,0)) | U3: =SUM(P3:T3) -> 3 | V3: =COUNT(P3:T3) -> 3 | W3: =IF(V3=0,0,U3/V3*100) -> 100 | X3: =C3&"_"&B3 -> gpt-4o-mini_C1_Hybrid
A4: full_benchmark_report1.json | B4: C1_Hybrid | C4: gpt-4o-mini | D4: 3 | E4: 10.89 | F4: 0.003843 | G4: 23014 | H4: 651 | I4: =G4+H4 -> 23665 | J4: 1 | K4: 934 | L4: 38 | M4: 39 | N4: 39 | O4: 839 | P4: =IF(OR('Ground-Truth'!$C$2<>"Ja",'Ground-Truth'!$D$2=""),"",IF(TEXT(K4,"0")=TEXT('Ground-Truth'!$D$2,"0"),1,0)) -> 0 | Q4: =IF(OR('Ground-Truth'!$C$3<>"Ja",'Ground-Truth'!$D$3=""),"",IF(TEXT(L4,"0")=TEXT('Ground-Truth'!$D$3,"0"),1,0)) -> 1 | R4: =IF(OR('Ground-Truth'!$C$4<>"Ja",'Ground-Truth'!$D$4=""),"",IF(TEXT(M4,"0")=TEXT('Ground-Truth'!$D$4,"0"),1,0)) -> 1 | S4: =IF(OR('Ground-Truth'!$C$5<>"Ja",'Ground-Truth'!$D$5=""),"",IF(TEXT(N4,"0")=TEXT('Ground-Truth'!$D$5,"0"),1,0)) | T4: =IF(OR('Ground-Truth'!$C$6<>"Ja",'Ground-Truth'!$D$6=""),"",IF(TEXT(O4,"0")=TEXT('Ground-Truth'!$D$6,"0"),1,0)) | U4: =SUM(P4:T4) -> 2 | V4: =COUNT(P4:T4) -> 3 | W4: =IF(V4=0,0,U4/V4*100) -> 66.666667 | X4: =C4&"_"&B4 -> gpt-4o-mini_C1_Hybrid
A5: full_benchmark_report1.json | B5: C1_Hybrid | C5: gpt-4o-mini | D5: 4 | E5: 12.9 | F5: 0.003922 | G5: 23014 | H5: 783 | I5: =G5+H5 -> 23797 | J5: 1 | K5: 934 | L5: 38 | M5: 39 | N5: 39 | O5: 839 | P5: =IF(OR('Ground-Truth'!$C$2<>"Ja",'Ground-Truth'!$D$2=""),"",IF(TEXT(K5,"0")=TEXT('Ground-Truth'!$D$2,"0"),1,0)) -> 0 | Q5: =IF(OR('Ground-Truth'!$C$3<>"Ja",'Ground-Truth'!$D$3=""),"",IF(TEXT(L5,"0")=TEXT('Ground-Truth'!$D$3,"0"),1,0)) -> 1 | R5: =IF(OR('Ground-Truth'!$C$4<>"Ja",'Ground-Truth'!$D$4=""),"",IF(TEXT(M5,"0")=TEXT('Ground-Truth'!$D$4,"0"),1,0)) -> 1 | S5: =IF(OR('Ground-Truth'!$C$5<>"Ja",'Ground-Truth'!$D$5=""),"",IF(TEXT(N5,"0")=TEXT('Ground-Truth'!$D$5,"0"),1,0)) | T5: =IF(OR('Ground-Truth'!$C$6<>"Ja",'Ground-Truth'!$D$6=""),"",IF(TEXT(O5,"0")=TEXT('Ground-Truth'!$D$6,"0"),1,0)) | U5: =SUM(P5:T5) -> 2 | V5: =COUNT(P5:T5) -> 3 | W5: =IF(V5=0,0,U5/V5*100) -> 66.666667 | X5: =C5&"_"&B5 -> gpt-4o-mini_C1_Hybrid
A6: full_benchmark_report1.json | B6: C1_Hybrid | C6: gpt-4o-mini | D6: 5 | E6: 15.97 | F6: 0.003879 | G6: 23014 | H6: 712 | I6: =G6+H6 -> 23726 | J6: 1 | K6: 934 | L6: 38 | M6: 39 | N6: 39 | O6: 839 | P6: =IF(OR('Ground-Truth'!$C$2<>"Ja",'Ground-Truth'!$D$2=""),"",IF(TEXT(K6,"0")=TEXT('Ground-Truth'!$D$2,"0"),1,0)) -> 0 | Q6: =IF(OR('Ground-Truth'!$C$3<>"Ja",'Ground-Truth'!$D$3=""),"",IF(TEXT(L6,"0")=TEXT('Ground-Truth'!$D$3,"0"),1,0)) -> 1 | R6: =IF(OR('Ground-Truth'!$C$4<>"Ja",'Ground-Truth'!$D$4=""),"",IF(TEXT(M6,"0")=TEXT('Ground-Truth'!$D$4,"0"),1,0)) -> 1 | S6: =IF(OR('Ground-Truth'!$C$5<>"Ja",'Ground-Truth'!$D$5=""),"",IF(TEXT(N6,"0")=TEXT('Ground-Truth'!$D$5,"0"),1,0)) | T6: =IF(OR('Ground-Truth'!$C$6<>"Ja",'Ground-Truth'!$D$6=""),"",IF(TEXT(O6,"0")=TEXT('Ground-Truth'!$D$6,"0"),1,0)) | U6: =SUM(P6:T6) -> 2 | V6: =COUNT(P6:T6) -> 3 | W6: =IF(V6=0,0,U6/V6*100) -> 66.666667 | X6: =C6&"_"&B6 -> gpt-4o-mini_C1_Hybrid
A7: full_benchmark_report1.json | B7: C2_Precision | C7: gpt-4o-mini | D7: 1 | E7: 13.24 | F7: 0.001341 | G7: 6576 | H7: 591 | I7: =G7+H7 -> 7167 | J7: 5 | K7: 864 | L7: 38 | M7: 39 | N7: 39 | O7: 823 | P7: =IF(OR('Ground-Truth'!$C$2<>"Ja",'Ground-Truth'!$D$2=""),"",IF(TEXT(K7,"0")=TEXT('Ground-Truth'!$D$2,"0"),1,0)) -> 1 | Q7: =IF(OR('Ground-Truth'!$C$3<>"Ja",'Ground-Truth'!$D$3=""),"",IF(TEXT(L7,"0")=TEXT('Ground-Truth'!$D$3,"0"),1,0)) -> 1 | R7: =IF(OR('Ground-Truth'!$C$4<>"Ja",'Ground-Truth'!$D$4=""),"",IF(TEXT(M7,"0")=TEXT('Ground-Truth'!$D$4,"0"),1,0)) -> 1 | S7: =IF(OR('Ground-Truth'!$C$5<>"Ja",'Ground-Truth'!$D$5=""),"",IF(TEXT(N7,"0")=TEXT('Ground-Truth'!$D$5,"0"),1,0)) | T7: =IF(OR('Ground-Truth'!$C$6<>"Ja",'Ground-Truth'!$D$6=""),"",IF(TEXT(O7,"0")=TEXT('Ground-Truth'!$D$6,"0"),1,0)) | U7: =SUM(P7:T7) -> 3 | V7: =COUNT(P7:T7) -> 3 | W7: =IF(V7=0,0,U7/V7*100) -> 100 | X7: =C7&"_"&B7 -> gpt-4o-mini_C2_Precision
A8: full_benchmark_report1.json | B8: C2_Precision | C8: gpt-4o-mini | D8: 2 | E8: 12.67 | F8: 0.0014 | G8: 6576 | H8: 689 | I8: =G8+H8 -> 7265 | J8: 5 | K8: 934 | L8: 38 | M8: 39 | N8: 39 | O8: 823 | P8: =IF(OR('Ground-Truth'!$C$2<>"Ja",'Ground-Truth'!$D$2=""),"",IF(TEXT(K8,"0")=TEXT('Ground-Truth'!$D$2,"0"),1,0)) -> 0 | Q8: =IF(OR('Ground-Truth'!$C$3<>"Ja",'Ground-Truth'!$D$3=""),"",IF(TEXT(L8,"0")=TEXT('Ground-Truth'!$D$3,"0"),1,0)) -> 1 | R8: =IF(OR('Ground-Truth'!$C$4<>"Ja",'Ground-Truth'!$D$4=""),"",IF(TEXT(M8,"0")=TEXT('Ground-Truth'!$D$4,"0"),1,0)) -> 1 | S8: =IF(OR('Ground-Truth'!$C$5<>"Ja",'Ground-Truth'!$D$5=""),"",IF(TEXT(N8,"0")=TEXT('Ground-Truth'!$D$5,"0"),1,0)) | T8: =IF(OR('Ground-Truth'!$C$6<>"Ja",'Ground-Truth'!$D$6=""),"",IF(TEXT(O8,"0")=TEXT('Ground-Truth'!$D$6,"0"),1,0)) | U8: =SUM(P8:T8) -> 2 | V8: =COUNT(P8:T8) -> 3 | W8: =IF(V8=0,0,U8/V8*100) -> 66.666667 | X8: =C8&"_"&B8 -> gpt-4o-mini_C2_Precision
A9: full_benchmark_report1.json | B9: C2_Precision | C9: gpt-4o-mini | D9: 3 | E9: 15.24 | F9: 0.001353 | G9: 6576 | H9: 611 | I9: =G9+H9 -> 7187 | J9: 5 | K9: 934 | L9: 38 | M9: 39 | N9: 39 | O9: 823 | P9: =IF(OR('Ground-Truth'!$C$2<>"Ja",'Ground-Truth'!$D$2=""),"",IF(TEXT(K9,"0")=TEXT('Ground-Truth'!$D$2,"0"),1,0)) -> 0 | Q9: =IF(OR('Ground-Truth'!$C$3<>"Ja",'Ground-Truth'!$D$3=""),"",IF(TEXT(L9,"0")=TEXT('Ground-Truth'!$D$3,"0"),1,0)) -> 1 | R9: =IF(OR('Ground-Truth'!$C$4<>"Ja",'Ground-Truth'!$D$4=""),"",IF(TEXT(M9,"0")=TEXT('Ground-Truth'!$D$4,"0"),1,0)) -> 1 | S9: =IF(OR('Ground-Truth'!$C$5<>"Ja",'Ground-Truth'!$D$5=""),"",IF(TEXT(N9,"0")=TEXT('Ground-Truth'!$D$5,"0"),1,0)) | T9: =IF(OR('Ground-Truth'!$C$6<>"Ja",'Ground-Truth'!$D$6=""),"",IF(TEXT(O9,"0")=TEXT('Ground-Truth'!$D$6,"0"),1,0)) | U9: =SUM(P9:T9) -> 2 | V9: =COUNT(P9:T9) -> 3 | W9: =IF(V9=0,0,U9/V9*100) -> 66.666667 | X9: =C9&"_"&B9 -> gpt-4o-mini_C2_Precision
A10: full_benchmark_report1.json | B10: C2_Precision | C10: gpt-4o-mini | D10: 4 | E10: 11.97 | F10: 0.00136 | G10: 6576 | H10: 623 | I10: =G10+H10 -> 7199 | J10: 5 | K10: 934 | L10: 38 | M10: 39 | N10: 39 | O10: 823 | P10: =IF(OR('Ground-Truth'!$C$2<>"Ja",'Ground-Truth'!$D$2=""),"",IF(TEXT(K10,"0")=TEXT('Ground-Truth'!$D$2,"0"),1,0)) -> 0 | Q10: =IF(OR('Ground-Truth'!$C$3<>"Ja",'Ground-Truth'!$D$3=""),"",IF(TEXT(L10,"0")=TEXT('Ground-Truth'!$D$3,"0"),1,0)) -> 1 | R10: =IF(OR('Ground-Truth'!$C$4<>"Ja",'Ground-Truth'!$D$4=""),"",IF(TEXT(M10,"0")=TEXT('Ground-Truth'!$D$4,"0"),1,0)) -> 1 | S10: =IF(OR('Ground-Truth'!$C$5<>"Ja",'Ground-Truth'!$D$5=""),"",IF(TEXT(N10,"0")=TEXT('Ground-Truth'!$D$5,"0"),1,0)) | T10: =IF(OR('Ground-Truth'!$C$6<>"Ja",'Ground-Truth'!$D$6=""),"",IF(TEXT(O10,"0")=TEXT('Ground-Truth'!$D$6,"0"),1,0)) | U10: =SUM(P10:T10) -> 2 | V10: =COUNT(P10:T10) -> 3 | W10: =IF(V10=0,0,U10/V10*100) -> 66.666667 | X10: =C10&"_"&B10 -> gpt-4o-mini_C2_Precision
A11: full_benchmark_report1.json | B11: C2_Precision | C11: gpt-4o-mini | D11: 5 | E11: 16.96 | F11: 0.001496 | G11: 6576 | H11: 849 | I11: =G11+H11 -> 7425 | J11: 5 | K11: 934 | L11: 38 | M11: 39 | N11: 39 | O11: 823 | P11: =IF(OR('Ground-Truth'!$C$2<>"Ja",'Ground-Truth'!$D$2=""),"",IF(TEXT(K11,"0")=TEXT('Ground-Truth'!$D$2,"0"),1,0)) -> 0 | Q11: =IF(OR('Ground-Truth'!$C$3<>"Ja",'Ground-Truth'!$D$3=""),"",IF(TEXT(L11,"0")=TEXT('Ground-Truth'!$D$3,"0"),1,0)) -> 1 | R11: =IF(OR('Ground-Truth'!$C$4<>"Ja",'Ground-Truth'!$D$4=""),"",IF(TEXT(M11,"0")=TEXT('Ground-Truth'!$D$4,"0"),1,0)) -> 1 | S11: =IF(OR('Ground-Truth'!$C$5<>"Ja",'Ground-Truth'!$D$5=""),"",IF(TEXT(N11,"0")=TEXT('Ground-Truth'!$D$5,"0"),1,0)) | T11: =IF(OR('Ground-Truth'!$C$6<>"Ja",'Ground-Truth'!$D$6=""),"",IF(TEXT(O11,"0")=TEXT('Ground-Truth'!$D$6,"0"),1,0)) | U11: =SUM(P11:T11) -> 2 | V11: =COUNT(P11:T11) -> 3 | W11: =IF(V11=0,0,U11/V11*100) -> 66.666667 | X11: =C11&"_"&B11 -> gpt-4o-mini_C2_Precision
A12: full_benchmark_report1.json | B12: C3_Single | C12: gpt-4o-mini | D12: 1 | E12: 21.34 | F12: 0.017291 | G12: 112054 | H12: 804 | I12: =G12+H12 -> 112858 | J12: 5 | K12: 864 | L12: 38 | M12: 39 | N12: 39 | O12: 839 | P12: =IF(OR('Ground-Truth'!$C$2<>"Ja",'Ground-Truth'!$D$2=""),"",IF(TEXT(K12,"0")=TEXT('Ground-Truth'!$D$2,"0"),1,0)) -> 1 | Q12: =IF(OR('Ground-Truth'!$C$3<>"Ja",'Ground-Truth'!$D$3=""),"",IF(TEXT(L12,"0")=TEXT('Ground-Truth'!$D$3,"0"),1,0)) -> 1 | R12: =IF(OR('Ground-Truth'!$C$4<>"Ja",'Ground-Truth'!$D$4=""),"",IF(TEXT(M12,"0")=TEXT('Ground-Truth'!$D$4,"0"),1,0)) -> 1 | S12: =IF(OR('Ground-Truth'!$C$5<>"Ja",'Ground-Truth'!$D$5=""),"",IF(TEXT(N12,"0")=TEXT('Ground-Truth'!$D$5,"0"),1,0)) | T12: =IF(OR('Ground-Truth'!$C$6<>"Ja",'Ground-Truth'!$D$6=""),"",IF(TEXT(O12,"0")=TEXT('Ground-Truth'!$D$6,"0"),1,0)) | U12: =SUM(P12:T12) -> 3 | V12: =COUNT(P12:T12) -> 3 | W12: =IF(V12=0,0,U12/V12*100) -> 100 | X12: =C12&"_"&B12 -> gpt-4o-mini_C3_Single
A13: full_benchmark_report1.json | B13: C3_Single | C13: gpt-4o-mini | D13: 2 | E13: 18.87 | F13: 0.017267 | G13: 112054 | H13: 765 | I13: =G13+H13 -> 112819 | J13: 5 | K13: 934 | L13: 38 | M13: 39 | N13: 39 | O13: 839 | P13: =IF(OR('Ground-Truth'!$C$2<>"Ja",'Ground-Truth'!$D$2=""),"",IF(TEXT(K13,"0")=TEXT('Ground-Truth'!$D$2,"0"),1,0)) -> 0 | Q13: =IF(OR('Ground-Truth'!$C$3<>"Ja",'Ground-Truth'!$D$3=""),"",IF(TEXT(L13,"0")=TEXT('Ground-Truth'!$D$3,"0"),1,0)) -> 1 | R13: =IF(OR('Ground-Truth'!$C$4<>"Ja",'Ground-Truth'!$D$4=""),"",IF(TEXT(M13,"0")=TEXT('Ground-Truth'!$D$4,"0"),1,0)) -> 1 | S13: =IF(OR('Ground-Truth'!$C$5<>"Ja",'Ground-Truth'!$D$5=""),"",IF(TEXT(N13,"0")=TEXT('Ground-Truth'!$D$5,"0"),1,0)) | T13: =IF(OR('Ground-Truth'!$C$6<>"Ja",'Ground-Truth'!$D$6=""),"",IF(TEXT(O13,"0")=TEXT('Ground-Truth'!$D$6,"0"),1,0)) | U13: =SUM(P13:T13) -> 2 | V13: =COUNT(P13:T13) -> 3 | W13: =IF(V13=0,0,U13/V13*100) -> 66.666667 | X13: =C13&"_"&B13 -> gpt-4o-mini_C3_Single
... A27: full_benchmark_report1.json | B27: C1_Hybrid | C27: gpt-5-nano | D27: 1 | E27: 163.62 | F27: 0.00531 | G27: 23013 | H27: 10399 | I27: =G27+H27 -> 33412 | J27: 1 | K27: 934 | L27: 38 | M27: 39 | N27: 839 | O27: 839 | P27: =IF(OR('Ground-Truth'!$C$2<>"Ja",'Ground-Truth'!$D$2=""),"",IF(TEXT(K27,"0")=TEXT('Ground-Truth'!$D$2,"0"),1,0)) -> 0 | Q27: =IF(OR('Ground-Truth'!$C$3<>"Ja",'Ground-Truth'!$D$3=""),"",IF(TEXT(L27,"0")=TEXT('Ground-Truth'!$D$3,"0"),1,0)) -> 1 | R27: =IF(OR('Ground-Truth'!$C$4<>"Ja",'Ground-Truth'!$D$4=""),"",IF(TEXT(M27,"0")=TEXT('Ground-Truth'!$D$4,"0"),1,0)) -> 1 | S27: =IF(OR('Ground-Truth'!$C$5<>"Ja",'Ground-Truth'!$D$5=""),"",IF(TEXT(N27,"0")=TEXT('Ground-Truth'!$D$5,"0"),1,0)) | T27: =IF(OR('Ground-Truth'!$C$6<>"Ja",'Ground-Truth'!$D$6=""),"",IF(TEXT(O27,"0")=TEXT('Ground-Truth'!$D$6,"0"),1,0)) | U27: =SUM(P27:T27) -> 2 | V27: =COUNT(P27:T27) -> 3 | W27: =IF(V27=0,0,U27/V27*100) -> 66.666667 | X27: =C27&"_"&B27 -> gpt-5-nano_C1_Hybrid
A28: full_benchmark_report1.json | B28: C1_Hybrid | C28: gpt-5-nano | D28: 2 | E28: 268.7 | F28: 0.004895 | G28: 23013 | H28: 9360 | I28: =G28+H28 -> 32373 | J28: 1 | K28: 934 | L28: 38 | M28: 934 | N28: 839 | P28: =IF(OR('Ground-Truth'!$C$2<>"Ja",'Ground-Truth'!$D$2=""),"",IF(TEXT(K28,"0")=TEXT('Ground-Truth'!$D$2,"0"),1,0)) -> 0 | Q28: =IF(OR('Ground-Truth'!$C$3<>"Ja",'Ground-Truth'!$D$3=""),"",IF(TEXT(L28,"0")=TEXT('Ground-Truth'!$D$3,"0"),1,0)) -> 1 | R28: =IF(OR('Ground-Truth'!$C$4<>"Ja",'Ground-Truth'!$D$4=""),"",IF(TEXT(M28,"0")=TEXT('Ground-Truth'!$D$4,"0"),1,0)) -> 0 | S28: =IF(OR('Ground-Truth'!$C$5<>"Ja",'Ground-Truth'!$D$5=""),"",IF(TEXT(N28,"0")=TEXT('Ground-Truth'!$D$5,"0"),1,0)) | T28: =IF(OR('Ground-Truth'!$C$6<>"Ja",'Ground-Truth'!$D$6=""),"",IF(TEXT(O28,"0")=TEXT('Ground-Truth'!$D$6,"0"),1,0)) | U28: =SUM(P28:T28) -> 1 | V28: =COUNT(P28:T28) -> 3 | W28: =IF(V28=0,0,U28/V28*100) -> 33.333333 | X28: =C28&"_"&B28 -> gpt-5-nano_C1_Hybrid
A29: full_benchmark_report1.json | B29: C1_Hybrid | C29: gpt-5-nano | D29: 3 | E29: 100.73 | F29: 0.005655 | G29: 23013 | H29: 11262 | I29: =G29+H29 -> 34275 | J29: 1 | K29: 934 | L29: 38 | M29: 39 | N29: 839 | O29: 839 | P29: =IF(OR('Ground-Truth'!$C$2<>"Ja",'Ground-Truth'!$D$2=""),"",IF(TEXT(K29,"0")=TEXT('Ground-Truth'!$D$2,"0"),1,0)) -> 0 | Q29: =IF(OR('Ground-Truth'!$C$3<>"Ja",'Ground-Truth'!$D$3=""),"",IF(TEXT(L29,"0")=TEXT('Ground-Truth'!$D$3,"0"),1,0)) -> 1 | R29: =IF(OR('Ground-Truth'!$C$4<>"Ja",'Ground-Truth'!$D$4=""),"",IF(TEXT(M29,"0")=TEXT('Ground-Truth'!$D$4,"0"),1,0)) -> 1 | S29: =IF(OR('Ground-Truth'!$C$5<>"Ja",'Ground-Truth'!$D$5=""),"",IF(TEXT(N29,"0")=TEXT('Ground-Truth'!$D$5,"0"),1,0)) | T29: =IF(OR('Ground-Truth'!$C$6<>"Ja",'Ground-Truth'!$D$6=""),"",IF(TEXT(O29,"0")=TEXT('Ground-Truth'!$D$6,"0"),1,0)) | U29: =SUM(P29:T29) -> 2 | V29: =COUNT(P29:T29) -> 3 | W29: =IF(V29=0,0,U29/V29*100) -> 66.666667 | X29: =C29&"_"&B29 -> gpt-5-nano_C1_Hybrid
A30: full_benchmark_report1.json | B30: C1_Hybrid | C30: gpt-5-nano | D30: 4 | E30: 119.77 | F30: 0.006009 | G30: 23013 | H30: 12146 | I30: =G30+H30 -> 35159 | J30: 1 | K30: 934 | L30: 38 | M30: 934 | N30: 838 | P30: =IF(OR('Ground-Truth'!$C$2<>"Ja",'Ground-Truth'!$D$2=""),"",IF(TEXT(K30,"0")=TEXT('Ground-Truth'!$D$2,"0"),1,0)) -> 0 | Q30: =IF(OR('Ground-Truth'!$C$3<>"Ja",'Ground-Truth'!$D$3=""),"",IF(TEXT(L30,"0")=TEXT('Ground-Truth'!$D$3,"0"),1,0)) -> 1 | R30: =IF(OR('Ground-Truth'!$C$4<>"Ja",'Ground-Truth'!$D$4=""),"",IF(TEXT(M30,"0")=TEXT('Ground-Truth'!$D$4,"0"),1,0)) -> 0 | S30: =IF(OR('Ground-Truth'!$C$5<>"Ja",'Ground-Truth'!$D$5=""),"",IF(TEXT(N30,"0")=TEXT('Ground-Truth'!$D$5,"0"),1,0)) | T30: =IF(OR('Ground-Truth'!$C$6<>"Ja",'Ground-Truth'!$D$6=""),"",IF(TEXT(O30,"0")=TEXT('Ground-Truth'!$D$6,"0"),1,0)) | U30: =SUM(P30:T30) -> 1 | V30: =COUNT(P30:T30) -> 3 | W30: =IF(V30=0,0,U30/V30*100) -> 33.333333 | X30: =C30&"_"&B30 -> gpt-5-nano_C1_Hybrid
A31: full_benchmark_report1.json | B31: C1_Hybrid | C31: gpt-5-nano | D31: 5 | E31: 86.36 | F31: 0.005463 | G31: 23013 | H31: 10781 | I31: =G31+H31 -> 33794 | J31: 1 | K31: 934 | L31: 38 | M31: 39 | N31: 934 | O31: 549 | P31: =IF(OR('Ground-Truth'!$C$2<>"Ja",'Ground-Truth'!$D$2=""),"",IF(TEXT(K31,"0")=TEXT('Ground-Truth'!$D$2,"0"),1,0)) -> 0 | Q31: =IF(OR('Ground-Truth'!$C$3<>"Ja",'Ground-Truth'!$D$3=""),"",IF(TEXT(L31,"0")=TEXT('Ground-Truth'!$D$3,"0"),1,0)) -> 1 | R31: =IF(OR('Ground-Truth'!$C$4<>"Ja",'Ground-Truth'!$D$4=""),"",IF(TEXT(M31,"0")=TEXT('Ground-Truth'!$D$4,"0"),1,0)) -> 1 | S31: =IF(OR('Ground-Truth'!$C$5<>"Ja",'Ground-Truth'!$D$5=""),"",IF(TEXT(N31,"0")=TEXT('Ground-Truth'!$D$5,"0"),1,0)) | T31: =IF(OR('Ground-Truth'!$C$6<>"Ja",'Ground-Truth'!$D$6=""),"",IF(TEXT(O31,"0")=TEXT('Ground-Truth'!$D$6,"0"),1,0)) | U31: =SUM(P31:T31) -> 2 | V31: =COUNT(P31:T31) -> 3 | W31: =IF(V31=0,0,U31/V31*100) -> 66.666667 | X31: =C31&"_"&B31 -> gpt-5-nano_C1_Hybrid
A32: full_benchmark_report1.json | B32: C2_Precision | C32: gpt-5-nano | D32: 1 | E32: 209.41 | F32: 0.010517 | G32: 6571 | H32: 25472 | I32: =G32+H32 -> 32043 | J32: 5 | K32: 934 | L32: 38 | M32: 39 | N32: 39 | O32: 839 | P32: =IF(OR('Ground-Truth'!$C$2<>"Ja",'Ground-Truth'!$D$2=""),"",IF(TEXT(K32,"0")=TEXT('Ground-Truth'!$D$2,"0"),1,0)) -> 0 | Q32: =IF(OR('Ground-Truth'!$C$3<>"Ja",'Ground-Truth'!$D$3=""),"",IF(TEXT(L32,"0")=TEXT('Ground-Truth'!$D$3,"0"),1,0)) -> 1 | R32: =IF(OR('Ground-Truth'!$C$4<>"Ja",'Ground-Truth'!$D$4=""),"",IF(TEXT(M32,"0")=TEXT('Ground-Truth'!$D$4,"0"),1,0)) -> 1 | S32: =IF(OR('Ground-Truth'!$C$5<>"Ja",'Ground-Truth'!$D$5=""),"",IF(TEXT(N32,"0")=TEXT('Ground-Truth'!$D$5,"0"),1,0)) | T32: =IF(OR('Ground-Truth'!$C$6<>"Ja",'Ground-Truth'!$D$6=""),"",IF(TEXT(O32,"0")=TEXT('Ground-Truth'!$D$6,"0"),1,0)) | U32: =SUM(P32:T32) -> 2 | V32: =COUNT(P32:T32) -> 3 | W32: =IF(V32=0,0,U32/V32*100) -> 66.666667 | X32: =C32&"_"&B32 -> gpt-5-nano_C2_Precision
A33: full_benchmark_report1.json | B33: C2_Precision | C33: gpt-5-nano | D33: 2 | E33: 155.43 | F33: 0.008354 | G33: 6571 | H33: 20064 | I33: =G33+H33 -> 26635 | J33: 5 | K33: 934 | L33: 38 | M33: 39 | N33: 39 | O33: 839 | P33: =IF(OR('Ground-Truth'!$C$2<>"Ja",'Ground-Truth'!$D$2=""),"",IF(TEXT(K33,"0")=TEXT('Ground-Truth'!$D$2,"0"),1,0)) -> 0 | Q33: =IF(OR('Ground-Truth'!$C$3<>"Ja",'Ground-Truth'!$D$3=""),"",IF(TEXT(L33,"0")=TEXT('Ground-Truth'!$D$3,"0"),1,0)) -> 1 | R33: =IF(OR('Ground-Truth'!$C$4<>"Ja",'Ground-Truth'!$D$4=""),"",IF(TEXT(M33,"0")=TEXT('Ground-Truth'!$D$4,"0"),1,0)) -> 1 | S33: =IF(OR('Ground-Truth'!$C$5<>"Ja",'Ground-Truth'!$D$5=""),"",IF(TEXT(N33,"0")=TEXT('Ground-Truth'!$D$5,"0"),1,0)) | T33: =IF(OR('Ground-Truth'!$C$6<>"Ja",'Ground-Truth'!$D$6=""),"",IF(TEXT(O33,"0")=TEXT('Ground-Truth'!$D$6,"0"),1,0)) | U33: =SUM(P33:T33) -> 2 | V33: =COUNT(P33:T33) -> 3 | W33: =IF(V33=0,0,U33/V33*100) -> 66.666667 | X33: =C33&"_"&B33 -> gpt-5-nano_C2_Precision
A34: full_benchmark_report1.json | B34: C2_Precision | C34: gpt-5-nano | D34: 3 | E34: 150.68 | F34: 0.008307 | G34: 6571 | H34: 19947 | I34: =G34+H34 -> 26518 | J34: 5 | K34: 934 | L34: 38 | M34: 39 | N34: 39 | O34: 839 | P34: =IF(OR('Ground-Truth'!$C$2<>"Ja",'Ground-Truth'!$D$2=""),"",IF(TEXT(K34,"0")=TEXT('Ground-Truth'!$D$2,"0"),1,0)) -> 0 | Q34: =IF(OR('Ground-Truth'!$C$3<>"Ja",'Ground-Truth'!$D$3=""),"",IF(TEXT(L34,"0")=TEXT('Ground-Truth'!$D$3,"0"),1,0)) -> 1 | R34: =IF(OR('Ground-Truth'!$C$4<>"Ja",'Ground-Truth'!$D$4=""),"",IF(TEXT(M34,"0")=TEXT('Ground-Truth'!$D$4,"0"),1,0)) -> 1 | S34: =IF(OR('Ground-Truth'!$C$5<>"Ja",'Ground-Truth'!$D$5=""),"",IF(TEXT(N34,"0")=TEXT('Ground-Truth'!$D$5,"0"),1,0)) | T34: =IF(OR('Ground-Truth'!$C$6<>"Ja",'Ground-Truth'!$D$6=""),"",IF(TEXT(O34,"0")=TEXT('Ground-Truth'!$D$6,"0"),1,0)) | U34: =SUM(P34:T34) -> 2 | V34: =COUNT(P34:T34) -> 3 | W34: =IF(V34=0,0,U34/V34*100) -> 66.666667 | X34: =C34&"_"&B34 -> gpt-5-nano_C2_Precision
A35: full_benchmark_report1.json | B35: C2_Precision | C35: gpt-5-nano | D35: 4 | E35: 206.35 | F35: 0.008153 | G35: 6571 | H35: 19560 | I35: =G35+H35 -> 26131 | J35: 5 | K35: 934 | L35: 38 | M35: 39 | N35: 39 | O35: 839 | P35: =IF(OR('Ground-Truth'!$C$2<>"Ja",'Ground-Truth'!$D$2=""),"",IF(TEXT(K35,"0")=TEXT('Ground-Truth'!$D$2,"0"),1,0)) -> 0 | Q35: =IF(OR('Ground-Truth'!$C$3<>"Ja",'Ground-Truth'!$D$3=""),"",IF(TEXT(L35,"0")=TEXT('Ground-Truth'!$D$3,"0"),1,0)) -> 1 | R35: =IF(OR('Ground-Truth'!$C$4<>"Ja",'Ground-Truth'!$D$4=""),"",IF(TEXT(M35,"0")=TEXT('Ground-Truth'!$D$4,"0"),1,0)) -> 1 | S35: =IF(OR('Ground-Truth'!$C$5<>"Ja",'Ground-Truth'!$D$5=""),"",IF(TEXT(N35,"0")=TEXT('Ground-Truth'!$D$5,"0"),1,0)) | T35: =IF(OR('Ground-Truth'!$C$6<>"Ja",'Ground-Truth'!$D$6=""),"",IF(TEXT(O35,"0")=TEXT('Ground-Truth'!$D$6,"0"),1,0)) | U35: =SUM(P35:T35) -> 2 | V35: =COUNT(P35:T35) -> 3 | W35: =IF(V35=0,0,U35/V35*100) -> 66.666667 | X35: =C35&"_"&B35 -> gpt-5-nano_C2_Precision
A36: full_benchmark_report1.json | B36: C2_Precision | C36: gpt-5-nano | D36: 5 | E36: 264.15 | F36: 0.008079 | G36: 6571 | H36: 19376 | I36: =G36+H36 -> 25947 | J36: 5 | K36: 934 | L36: 38 | M36: 39 | N36: 39 | O36: 839 | P36: =IF(OR('Ground-Truth'!$C$2<>"Ja",'Ground-Truth'!$D$2=""),"",IF(TEXT(K36,"0")=TEXT('Ground-Truth'!$D$2,"0"),1,0)) -> 0 | Q36: =IF(OR('Ground-Truth'!$C$3<>"Ja",'Ground-Truth'!$D$3=""),"",IF(TEXT(L36,"0")=TEXT('Ground-Truth'!$D$3,"0"),1,0)) -> 1 | R36: =IF(OR('Ground-Truth'!$C$4<>"Ja",'Ground-Truth'!$D$4=""),"",IF(TEXT(M36,"0")=TEXT('Ground-Truth'!$D$4,"0"),1,0)) -> 1 | S36: =IF(OR('Ground-Truth'!$C$5<>"Ja",'Ground-Truth'!$D$5=""),"",IF(TEXT(N36,"0")=TEXT('Ground-Truth'!$D$5,"0"),1,0)) | T36: =IF(OR('Ground-Truth'!$C$6<>"Ja",'Ground-Truth'!$D$6=""),"",IF(TEXT(O36,"0")=TEXT('Ground-Truth'!$D$6,"0"),1,0)) | U36: =SUM(P36:T36) -> 2 | V36: =COUNT(P36:T36) -> 3 | W36: =IF(V36=0,0,U36/V36*100) -> 66.666667 | X36: =C36&"_"&B36 -> gpt-5-nano_C2_Precision
A37: full_benchmark_report1.json | B37: C3_Single | C37: gpt-5-nano | D37: 1 | E37: 302.29 | F37: 0.012678 | G37: 112049 | H37: 17689 | I37: =G37+H37 -> 129738 | J37: 5 | K37: 934 | L37: 38 | M37: 39 | N37: 934 | O37: 549 | P37: =IF(OR('Ground-Truth'!$C$2<>"Ja",'Ground-Truth'!$D$2=""),"",IF(TEXT(K37,"0")=TEXT('Ground-Truth'!$D$2,"0"),1,0)) -> 0 | Q37: =IF(OR('Ground-Truth'!$C$3<>"Ja",'Ground-Truth'!$D$3=""),"",IF(TEXT(L37,"0")=TEXT('Ground-Truth'!$D$3,"0"),1,0)) -> 1 | R37: =IF(OR('Ground-Truth'!$C$4<>"Ja",'Ground-Truth'!$D$4=""),"",IF(TEXT(M37,"0")=TEXT('Ground-Truth'!$D$4,"0"),1,0)) -> 1 | S37: =IF(OR('Ground-Truth'!$C$5<>"Ja",'Ground-Truth'!$D$5=""),"",IF(TEXT(N37,"0")=TEXT('Ground-Truth'!$D$5,"0"),1,0)) | T37: =IF(OR('Ground-Truth'!$C$6<>"Ja",'Ground-Truth'!$D$6=""),"",IF(TEXT(O37,"0")=TEXT('Ground-Truth'!$D$6,"0"),1,0)) | U37: =SUM(P37:T37) -> 2 | V37: =COUNT(P37:T37) -> 3 | W37: =IF(V37=0,0,U37/V37*100) -> 66.666667 | X37: =C37&"_"&B37 -> gpt-5-nano_C3_Single
A38: full_benchmark_report1.json | B38: C3_Single | C38: gpt-5-nano | D38: 2 | E38: 213.4 | F38: 0.011836 | G38: 112049 | H38: 15583 | I38: =G38+H38 -> 127632 | J38: 5 | K38: 934 | L38: 38 | M38: 39 | N38: 39 | O38: 549 | P38: =IF(OR('Ground-Truth'!$C$2<>"Ja",'Ground-Truth'!$D$2=""),"",IF(TEXT(K38,"0")=TEXT('Ground-Truth'!$D$2,"0"),1,0)) -> 0 | Q38: =IF(OR('Ground-Truth'!$C$3<>"Ja",'Ground-Truth'!$D$3=""),"",IF(TEXT(L38,"0")=TEXT('Ground-Truth'!$D$3,"0"),1,0)) -> 1 | R38: =IF(OR('Ground-Truth'!$C$4<>"Ja",'Ground-Truth'!$D$4=""),"",IF(TEXT(M38,"0")=TEXT('Ground-Truth'!$D$4,"0"),1,0)) -> 1 | S38: =IF(OR('Ground-Truth'!$C$5<>"Ja",'Ground-Truth'!$D$5=""),"",IF(TEXT(N38,"0")=TEXT('Ground-Truth'!$D$5,"0"),1,0)) | T38: =IF(OR('Ground-Truth'!$C$6<>"Ja",'Ground-Truth'!$D$6=""),"",IF(TEXT(O38,"0")=TEXT('Ground-Truth'!$D$6,"0"),1,0)) | U38: =SUM(P38:T38) -> 2 | V38: =COUNT(P38:T38) -> 3 | W38: =IF(V38=0,0,U38/V38*100) -> 66.666667 | X38: =C38&"_"&B38 -> gpt-5-nano_C3_Single
A39: full_benchmark_report1.json | B39: C3_Single | C39: gpt-5-nano | D39: 3 | E39: 240.42 | F39: 0.012882 | G39: 112049 | H39: 18199 | I39: =G39+H39 -> 130248 | J39: 5 | K39: 934 | L39: 38 | M39: 39 | N39: 39 | O39: 839 | P39: =IF(OR('Ground-Truth'!$C$2<>"Ja",'Ground-Truth'!$D$2=""),"",IF(TEXT(K39,"0")=TEXT('Ground-Truth'!$D$2,"0"),1,0)) -> 0 | Q39: =IF(OR('Ground-Truth'!$C$3<>"Ja",'Ground-Truth'!$D$3=""),"",IF(TEXT(L39,"0")=TEXT('Ground-Truth'!$D$3,"0"),1,0)) -> 1 | R39: =IF(OR('Ground-Truth'!$C$4<>"Ja",'Ground-Truth'!$D$4=""),"",IF(TEXT(M39,"0")=TEXT('Ground-Truth'!$D$4,"0"),1,0)) -> 1 | S39: =IF(OR('Ground-Truth'!$C$5<>"Ja",'Ground-Truth'!$D$5=""),"",IF(TEXT(N39,"0")=TEXT('Ground-Truth'!$D$5,"0"),1,0)) | T39: =IF(OR('Ground-Truth'!$C$6<>"Ja",'Ground-Truth'!$D$6=""),"",IF(TEXT(O39,"0")=TEXT('Ground-Truth'!$D$6,"0"),1,0)) | U39: =SUM(P39:T39) -> 2 | V39: =COUNT(P39:T39) -> 3 | W39: =IF(V39=0,0,U39/V39*100) -> 66.666667 | X39: =C39&"_"&B39 -> gpt-5-nano_C3_Single
A40: full_benchmark_report1.json | B40: C3_Single | C40: gpt-5-nano | D40: 4 | E40: 186.76 | F40: 0.013539 | G40: 112049 | H40: 19841 | I40: =G40+H40 -> 131890 | J40: 5 | K40: 934 | L40: 38 | M40: 934 | N40: 39 | O40: 549 | P40: =IF(OR('Ground-Truth'!$C$2<>"Ja",'Ground-Truth'!$D$2=""),"",IF(TEXT(K40,"0")=TEXT('Ground-Truth'!$D$2,"0"),1,0)) -> 0 | Q40: =IF(OR('Ground-Truth'!$C$3<>"Ja",'Ground-Truth'!$D$3=""),"",IF(TEXT(L40,"0")=TEXT('Ground-Truth'!$D$3,"0"),1,0)) -> 1 | R40: =IF(OR('Ground-Truth'!$C$4<>"Ja",'Ground-Truth'!$D$4=""),"",IF(TEXT(M40,"0")=TEXT('Ground-Truth'!$D$4,"0"),1,0)) -> 0 | S40: =IF(OR('Ground-Truth'!$C$5<>"Ja",'Ground-Truth'!$D$5=""),"",IF(TEXT(N40,"0")=TEXT('Ground-Truth'!$D$5,"0"),1,0)) | T40: =IF(OR('Ground-Truth'!$C$6<>"Ja",'Ground-Truth'!$D$6=""),"",IF(TEXT(O40,"0")=TEXT('Ground-Truth'!$D$6,"0"),1,0)) | U40: =SUM(P40:T40) -> 1 | V40: =COUNT(P40:T40) -> 3 | W40: =IF(V40=0,0,U40/V40*100) -> 33.333333 | X40: =C40&"_"&B40 -> gpt-5-nano_C3_Single
A41: full_benchmark_report1.json | B41: C3_Single | C41: gpt-5-nano | D41: 5 | E41: 190.1 | F41: 0.014075 | G41: 112049 | H41: 21181 | I41: =G41+H41 -> 133230 | J41: 5 | K41: 934 | L41: 38 | M41: 39 | N41: 934 | O41: 549 | P41: =IF(OR('Ground-Truth'!$C$2<>"Ja",'Ground-Truth'!$D$2=""),"",IF(TEXT(K41,"0")=TEXT('Ground-Truth'!$D$2,"0"),1,0)) -> 0 | Q41: =IF(OR('Ground-Truth'!$C$3<>"Ja",'Ground-Truth'!$D$3=""),"",IF(TEXT(L41,"0")=TEXT('Ground-Truth'!$D$3,"0"),1,0)) -> 1 | R41: =IF(OR('Ground-Truth'!$C$4<>"Ja",'Ground-Truth'!$D$4=""),"",IF(TEXT(M41,"0")=TEXT('Ground-Truth'!$D$4,"0"),1,0)) -> 1 | S41: =IF(OR('Ground-Truth'!$C$5<>"Ja",'Ground-Truth'!$D$5=""),"",IF(TEXT(N41,"0")=TEXT('Ground-Truth'!$D$5,"0"),1,0)) | T41: =IF(OR('Ground-Truth'!$C$6<>"Ja",'Ground-Truth'!$D$6=""),"",IF(TEXT(O41,"0")=TEXT('Ground-Truth'!$D$6,"0"),1,0)) | U41: =SUM(P41:T41) -> 2 | V41: =COUNT(P41:T41) -> 3 | W41: =IF(V41=0,0,U41/V41*100) -> 66.666667 | X41: =C41&"_"&B41 -> gpt-5-nano_C3_Single
